Workbook

Sheet Start here
A1: Breakout 4B · compute it yourself, from the raw data
A3: Each sprint has one sheet where your group computes the numbers with ordinary Excel tools, from the data both administrations hold: the customs registers and declaration lines, the tax register and the VAT returns. 4B_lab.xlsx shows every number already computed; here you learn how they are made. When your number is right, the Check cell turns green.
A4: Colours: yellow = you type here (a number or a formula). Grey = given or worked for you. Purple = computed for you (a helper: string similarity, a model score, a median per sector); the Fields sheet says how. Navy = column names. Every threshold sits on the Parameters sheet.
A5: Stuck? Hint 1 is beside each step. Hint 2, the full formula, is on the Hints sheet and on the site. The coach (coach-4b) helps one step at a time. 4B_compute_worked.xlsx shows every formula filled in.
A7: When | B7: Sheet | D7: What you compute
A8: Sprint 1 | B8: S1 Match | D8: The 25 importers against the tax register: the exact join on the tax number, the match confidence from the similarities, the class at the dial. I17 is worked.
A9: Sprint 1 | B9: S1 Track B | D9: A real register: precision and recall on the labelled sample at three settings of the dial.
A10: Sprint 2 | B10: S2 Four lists | D10: From the declaration lines and the VAT returns: imports and import VAT paid, returns filed, import VAT deducted, sales; the four questions in order; VAT at stake; list 4 ranked and cut at the capacity. I01 is worked.
A11: Sprint 3 | B11: S3 Network | D11: From the customs registers: what each tax number serves (names, consignees, addresses, brokers), the rule, and what the tax register says about its director.
A12: Sprint 4 | B12: S4 Tax feeds customs | D12: With the tax audit file: does a tax adjustment found at random point to customs findings? The customs hit rate with and without a tax adjustment, and the lift.
A14: Everything in this workbook is synthetic (release data-v13). Published customs datasets record an irregularity on 1 to 8 lines in 100; in this lab the random draw finds 3 in 100.

Sheet Parameters
A1: Parameters · every threshold of the breakout in one place
A2: Every formula reads its threshold here. Change one, and every sheet follows. The weights and the dial are choices: say them out loud.
A4: parameter | B4: value | C4: note
A5: Weight of the name similarity | B5: 0.4 | C5: The deck's recipe; a choice, not a measurement.
A6: Weight of the address similarity | B6: 0.3 | C6: Idem.
A7: Weight of the director similarity | B7: 0.3 | C7: Idem.
A8: Dial: a link at or above | B8: 0.9 | C8: Set on the labelled sample (S1 Track B).
A9: Dial: a person reviews at or above | B9: 0.7 | C9: Below it: no link.
A10: VAT rate | B10: 0.1 | C10: The lab's rate.
A11: First period number of the last six returns | B11: 19 | C11: Periods 19 to 24 = 2026-04 to 2026-09.
A12: First period number of the last twelve returns | B12: 13 | C12: Periods 13 to 24 = 2025-10 to 2026-09.
A13: First customs month of the last twelve months | B13: 25 | C13: Months 25 to 36 = 2025-10 to 2026-09.
A14: Filing: at least this many of the last six returns | B14: 5 | C14: Question 2.
A15: Imports in its books: deducted ÷ paid at least | B15: 0.5 | C15: Question 3.
A16: Sold: sales ÷ imports at least | B16: 1 | C16: Question 4.
... A20: Network rule: turnover ÷ imports under | B20: 0.2 | C20: The 4B rule.

Sheet Tax register
A1: The tax register · 1,799 taxpayers as the tax administration holds them
A4: tax ID | B4: legal name | C4: trading name | D4: address | E4: district | F4: phone | G4: director | H4: registered on | I4: VAT registered | J4: status | K4: sector
A5: T100004 | B5: Metro Trading Co., Ltd | D5: Unit 21, 369 Airport Road | E5: North | F5: 0800178993 | G5: A. Tanaka | H5: 2022-08-09 | I5: TRUE | J5: active | K5: Vehicles and parts
A6: T100013 | B6: Prescott Imports Group Ltd | D6: 102 Temple Street | E6: East | F6: 0725292216 | G6: Kenji Mwangi | H6: 2023-03-18 | I6: TRUE | J6: active | K6: Vehicles and parts
A7: T100016 | B7: Saffron Trading & Sons | D7: 53 Garden Lane | E7: Capital | F7: 0471812185 | G7: Omar Rahman | H7: 2014-11-05 | I7: TRUE | J7: dormant | K7: General trading
A8: T100025 | B8: Harmony Fruits Co., Ltd | C8: Harmony Fruits Co., Ltd | D8: 297 Airport Road | E8: North | F8: 0328461006 | G8: Nadia Sato | H8: 2009-06-03 | I8: TRUE | J8: active | K8: Vehicles and parts
A9: T100033 | B9: Central Foods Limited | C9: Central Foods Limited | D9: 24 Harbour Road | E9: East | F9: 0401520138 | G9: Farid Ibrahim | H9: 2020-05-16 | I9: TRUE | J9: active | K9: Steel and construction
A10: T100038 | B10: Saffron Textiles Co. | C10: Saffron Textiles Co. | D10: 8 MILL ROAD | E10: North | F10: 0690619802 | G10: Grace Silva | H10: 2018-05-04 | I10: TRUE | J10: active | K10: Textiles and apparel
A11: T100052 | B11: Twin Rivers Textiles & Sons | D11: 321 Riverside | E11: South | F11: 0879024230 | G11: Amina Osei | H11: 2022-12-08 | I11: TRUE | J11: active | K11: Furniture and household
A12: T100056 | B12: Green Valley Imports Group Ltd | C12: Green Valley Imports Group Ltd | D12: 16 Industrial Estate | E12: West | F12: 0999463247 | G12: Somchai Osei | H12: 2008-08-25 | I12: TRUE | J12: active | K12: Steel and construction
A13: T100064 | B13: Aldergate Trading Company | D13: 71 Bazaar Lane | E13: Capital | F13: 0459332927 | G13: Omar Sato | H13: 2012-02-13 | I13: TRUE | J13: active | K13: Tobacco and beverages
A14: T100070 | B14: Silk Road Steel Co. | C14: Silk Road Steel Co. | D14: 346 Market Street | E14: North | F14: 0519965779 | G14: Farid Haddad | H14: 2010-12-11 | I14: TRUE | J14: active | K14: Pharmaceuticals
A15: T100082 | B15: Harmony Trading & Sons | D15: 199 Bazaar Lane | E15: North | F15: 0405422879 | G15: Amina Ibrahim | H15: 2014-09-01 | I15: TRUE | J15: active | K15: Steel and construction
A16: T100090 | B16: Twin Rivers Glow International Limited | C16: Twin Rivers Glow International Ltd | D16: Unit 10, 37 Station Road | E16: West | F16: 0232613013 | G16: Tomas Sato | H16: 2015-10-21 | I16: TRUE | J16: active | K16: Textiles and apparel
A17: T100097 | B17: Silk Road Industries Company | C17: Silk Depot | D17: 23 Airport Road | E17: East | F17: 0387995973 | G17: Priya Haddad | H17: 2010-07-10 | I17: TRUE | J17: active | K17: General trading
A18: T100104 | B18: Silver Logistics Co., Ltd | C18: Silver Logistics Co., Ltd | D18: 239 Airport Road | E18: Capital | F18: 0967270280 | G18: Samuel Sato | H18: 2015-02-11 | I18: TRUE | J18: active | K18: Textiles and apparel
A19: T100105 | B19: Saffron Electronics International Ltd | D19: 180 Garden Lane | E19: North | F19: 0413172306 | G19: Ravi Kowalski | H19: 2019-09-29 | I19: TRUE | J19: active | K19: Vehicles and parts
A20: T100116 | B20: Lotus Supply Partners Ltd | C20: Lotus Supply Partners Ltd | D20: 165 AIRPORT ROAD | E20: South | F20: 0297464461 | G20: Elena Haddad | H20: 2011-01-26 | I20: TRUE | J20: active | K20: Cosmetics and personal care
A21: T100119 | B21: Eastern Electronics & Sons | C21: Eastern Electronics & Sons | D21: 200 Harbour Road | E21: Coastal | F21: 0254068681 | G21: Nadia Sato | H21: 2011-03-15 | I21: TRUE | J21: active | K21: Cosmetics and personal care
A22: T100130 | B22: Royal Fruits Holdings Ltd | D22: 313 Market Street | E22: South | F22: 0269581004 | G22: B. Fernandes | H22: 2022-03-30 | I22: TRUE | J22: active | K22: Vehicles and parts
A23: T100134 | B23: Central Commercial Enterprises | C23: Central Commercial Enterprises | D23: Unit 13, 218 Industrial Estate | E23: East | F23: 0945440269 | G23: Priya Patel | H23: 2018-02-11 | I23: TRUE | J23: active | K23: Tobacco and beverages
A24: T100144 | B24: Crown Textiles & Sons | D24: 230 Garden Lane | E24: West | F24: 0806964313 | G24: Joseph Tanaka | H24: 2025-02-26 | I24: TRUE | J24: active | K24: Pharmaceuticals
A25: T100152 | B25: Crown Glow Group Limited | C25: Crown Glow Group Ltd | D25: 256 Market Street | E25: West | F25: 0980794230 | G25: Aisha Patel | H25: 2021-07-12 | I25: TRUE | J25: active | K25: Tobacco and beverages
A26: T100155 | B26: Silver Enterprises Limited | C26: Silver Enterprises Limited | D26: 21 Station Road | E26: South | F26: 0601335760 | G26: Ravi Sato | H26: 2013-11-30 | I26: TRUE | J26: active | K26: Textiles and apparel
A27: T100165 | B27: Pacific Glow Company | C27: Pacific Glow Co. | D27: 106 Station Rd | E27: Coastal | F27: 0229991183 | G27: Kenji Chen | H27: 2011-05-17 | I27: TRUE | J27: dormant | K27: Electronics
A28: T100173 | B28: Coral Supply Limited | C28: Coral Supply Limited | D28: 323 Bazaar Lane | E28: Coastal | F28: 0873719125 | G28: M. Sato | H28: 2025-11-14 | I28: TRUE | J28: active | K28: Food importers
A29: T100177 | B29: Aldergate Supply Co., Ltd | D29: 153 HARBOUR ROAD | E29: South | F29: 0229299704 | G29: Omar Haddad | H29: 2018-06-02 | I29: TRUE | J29: active | K29: Vehicles and parts
A30: T100193 | B30: Inverness Agro Co. | C30: Inverness Agro Co. | D30: 206 BAZAAR LANE | E30: Capital | F30: 0580341553 | G30: Daniel Mahmood | H30: 2009-07-06 | I30: TRUE | J30: active | K30: Fuel and chemicals
A31: T100201 | B31: Global Glow Limited | C31: Global Glow Ltd | D31: Unit 19, 83 Temple Street | E31: East | F31: 0510129904 | G31: Samuel Patel | H31: 2012-05-14 | I31: TRUE | J31: active | K31: Food importers
A32: T100208 | B32: Evergreen Pack Partners Limited | D32: 267 Riverside | E32: Coastal | F32: 0502506634 | G32: Samuel Okafor | H32: 2016-01-26 | I32: TRUE | J32: active | K32: Cosmetics and personal care
A33: T100211 | B33: Metro Living Partners Ltd | D33: 381 Temple Street | E33: South | F33: 0986965771 | G33: Daniel Ibrahim | H33: 2010-06-03 | I33: TRUE | J33: active | K33: Furniture and household
A34: T100219 | B34: Ashcombe Motors Co. | C34: Ashcombe Motors Co. | D34: 90 AIRPORT ROAD | E34: East | F34: 0611073084 | G34: Omar Rahman | H34: 2022-04-19 | I34: TRUE | J34: active | K34: Machinery
A35: T100225 | B35: Global Agro International Ltd | C35: Global Depot | D35: 260 Harbour Road | E35: Capital | F35: 0531652277 | G35: Amina Mensah | H35: 2020-11-14 | I35: TRUE | J35: active | K35: General trading
A36: T100236 | B36: Arden Supply Holdings Ltd | C36: Arden Supply Holdings Ltd | D36: 235 Mill Road | E36: North | F36: 0380927935 | G36: Grace Tanaka | H36: 2014-11-15 | I36: TRUE | J36: active | K36: Medical devices
A37: T100242 | B37: Metro Fruits Co. | C37: Metro Fruits Co. | D37: 139 Airport Road | E37: Coastal | F37: 0581524750 | G37: Omar Sato | H37: 2012-10-22 | I37: TRUE | J37: active | K37: Cosmetics and personal care
A38: T100251 | B38: Horizon Glow Co., Ltd | C38: Horizon Glow Co., Ltd | D38: 354 GARDEN LANE | E38: Capital | F38: 0719900946 | G38: Somchai Chen | H38: 2009-08-26 | I38: TRUE | J38: active | K38: Machinery
A39: T100257 | B39: Carrick Agro & Sons | D39: 320 Temple Street | E39: East | F39: 0506676501 | G39: Aisha Al-Sayed | H39: 2014-04-20 | I39: TRUE | J39: active | K39: Steel and construction
A40: T100260 | B40: Prescott Steel Holdings Ltd | C40: Prescott Steel Holdings Ltd | D40: 228 Industrial Estate | E40: North | F40: 0768739530 | G40: Tomas Mensah | H40: 2020-01-02 | I40: TRUE | J40: active | K40: Pharmaceuticals
A41: T100272 | B41: Central Imports Partners Limited | D41: 294 Station Rd | E41: East | F41: 0407340201 | G41: Ravi Bauer | H41: 2009-07-04 | I41: TRUE | J41: active | K41: Fuel and chemicals
A42: T100277 | B42: Delta Foods Limited | D42: 96 Garden Lane | E42: Coastal | F42: 0616961808 | G42: Samuel Patel | H42: 2011-01-17 | I42: TRUE | J42: active | K42: Textiles and apparel
...

Sheet Customs importers
A1: The customs importer register · 1,502 importer codes as customs holds them
A2: Columns K and L are yours (sprint 3): 1 the first time an address, or a broker, appears under a tax number. Rows 6 to 15 are worked.
A5: importer | B5: tax number | C5: legal name | D5: address | E5: district | F5: phone | G5: director | H5: default broker | I5: registered on | J5: sector | K5: first address under the number (1/0) | L5: first broker under the number (1/0)
A6: IMP00001 | B6: T100004 | C6: Metro Trading Co., Ltd | D6: 369 Airport Road | E6: North | F6: 0800178993 | G6: Aisha Tanaka | H6: BRK060 | I6: 2022-08-23 | J6: Vehicles and parts | K6: =IF(B6="","",IF(COUNTIFS($B$6:B6,B6,$D$6:D6,D6)=1,1,0)) | L6: =IF(B6="","",IF(COUNTIFS($B$6:B6,B6,$H$6:H6,H6)=1,1,0))
A7: IMP00002 | B7: T100013 | C7: Prescott Imports Group Ltd | D7: 102 Temple Street | E7: East | F7: 0844703272 | G7: Kenji Mwangi | H7: BRK078 | I7: 2022-05-14 | J7: Vehicles and parts | K7: =IF(B7="","",IF(COUNTIFS($B$6:B7,B7,$D$6:D7,D7)=1,1,0)) | L7: =IF(B7="","",IF(COUNTIFS($B$6:B7,B7,$H$6:H7,H7)=1,1,0))
A8: IMP00003 | B8: T100016 | C8: Saffron Trading & Sons | D8: 53 Garden Lane | E8: Capital | F8: 0973133835 | G8: Omar Rahman | H8: BRK054 | I8: 2014-02-07 | J8: General trading | K8: =IF(B8="","",IF(COUNTIFS($B$6:B8,B8,$D$6:D8,D8)=1,1,0)) | L8: =IF(B8="","",IF(COUNTIFS($B$6:B8,B8,$H$6:H8,H8)=1,1,0))
A9: IMP00004 | B9: T100025 | C9: Harmony Fruits Co., Ltd | D9: 297 Airport Road | E9: North | F9: 0328461006 | G9: Nadia Sato | H9: BRK080 | I9: 2008-08-08 | J9: Vehicles and parts | K9: =IF(B9="","",IF(COUNTIFS($B$6:B9,B9,$D$6:D9,D9)=1,1,0)) | L9: =IF(B9="","",IF(COUNTIFS($B$6:B9,B9,$H$6:H9,H9)=1,1,0))
A10: IMP00005 | B10: T100033 | C10: Central Foods Limited | D10: 24 Harbour Road | E10: East | F10: 0401520138 | G10: Farid Ibrahim | H10: BRK033 | I10: 2019-08-31 | J10: Steel and construction | K10: =IF(B10="","",IF(COUNTIFS($B$6:B10,B10,$D$6:D10,D10)=1,1,0)) | L10: =IF(B10="","",IF(COUNTIFS($B$6:B10,B10,$H$6:H10,H10)=1,1,0))
A11: IMP00006 | B11: T100033 | C11: Saffron Textiles Co. | D11: 8 Mill Road | E11: North | F11: 0690619802 | G11: Grace Silva | H11: BRK059 | I11: 2017-06-10 | J11: Textiles and apparel | K11: =IF(B11="","",IF(COUNTIFS($B$6:B11,B11,$D$6:D11,D11)=1,1,0)) | L11: =IF(B11="","",IF(COUNTIFS($B$6:B11,B11,$H$6:H11,H11)=1,1,0))
A12: IMP00007 | C12: Silk Road Enterprises Partners Ltd | D12: 241 Bazaar Lane | E12: Capital | F12: 0728834594 | G12: Somchai Al-Sayed | H12: BRK059 | I12: 2021-08-31 | J12: Tobacco and beverages | K12: =IF(B12="","",IF(COUNTIFS($B$6:B12,B12,$D$6:D12,D12)=1,1,0)) | L12: =IF(B12="","",IF(COUNTIFS($B$6:B12,B12,$H$6:H12,H12)=1,1,0))
A13: IMP00008 | B13: T100052 | C13: Twin Rivers Textiles & Sons | D13: 179 Harbour Road | E13: South | F13: 0879024230 | G13: Amina Osei | H13: BRK070 | I13: 2022-02-18 | J13: Furniture and household | K13: =IF(B13="","",IF(COUNTIFS($B$6:B13,B13,$D$6:D13,D13)=1,1,0)) | L13: =IF(B13="","",IF(COUNTIFS($B$6:B13,B13,$H$6:H13,H13)=1,1,0))
A14: IMP00009 | B14: T100056 | C14: Green Valley Imports Group Ltd | D14: 16 Industrial Estate | E14: West | F14: 0999463247 | G14: Somchai Osei | H14: BRK055 | I14: 2008-06-17 | J14: Steel and construction | K14: =IF(B14="","",IF(COUNTIFS($B$6:B14,B14,$D$6:D14,D14)=1,1,0)) | L14: =IF(B14="","",IF(COUNTIFS($B$6:B14,B14,$H$6:H14,H14)=1,1,0))
A15: IMP00010 | B15: T800064 | C15: Aldergate Trading Co. | D15: 71 Bazaar Lane | E15: Capital | F15: 0459332927 | G15: Omar Sato | H15: BRK071 | I15: 2011-08-14 | J15: Tobacco and beverages | K15: =IF(B15="","",IF(COUNTIFS($B$6:B15,B15,$D$6:D15,D15)=1,1,0)) | L15: =IF(B15="","",IF(COUNTIFS($B$6:B15,B15,$H$6:H15,H15)=1,1,0))
A16: IMP00011 | B16: T100070 | C16: Silk Road Steel Co. | D16: 346 Market Street | E16: North | F16: 0519965779 | G16: Farid Haddad | H16: BRK015 | I16: 2010-02-24 | J16: Pharmaceuticals
A17: IMP00012 | B17: T100082 | C17: Harmony Trading & Sons | D17: 199 Bazaar Lane | E17: North | F17: 0405422879 | G17: Amina Ibrahim | H17: BRK032 | I17: 2013-11-18 | J17: Steel and construction
A18: IMP00013 | B18: T100090 | C18: Twin Rivers Glow International Ltd | D18: 399 Temple Street | E18: West | F18: 0232613013 | G18: Tomas Sato | H18: BRK078 | I18: 2015-09-23 | J18: Textiles and apparel
A19: IMP00014 | B19: T100097 | C19: Silk Road Industries Co. | D19: 23 Airport Road | E19: East | F19: 0387995973 | G19: Priya Haddad | H19: BRK067 | I19: 2010-08-22 | J19: General trading
A20: IMP00015 | B20: T100104 | C20: Silver Logistics Co., Ltd | D20: 239 Airport Road | E20: Capital | F20: 0320904779 | G20: Samuel Sato | H20: BRK034 | I20: 2014-07-26 | J20: Textiles and apparel
A21: IMP00016 | B21: T100105 | C21: Saffron Electronics International Ltd | D21: 180 Garden Lane | E21: North | F21: 0413172306 | G21: Ravi Kowalski | H21: BRK049 | I21: 2019-05-04 | J21: Vehicles and parts
A22: IMP00017 | B22: T100116 | C22: Lotus Supply Partners Ltd | D22: 165 Airport Road | E22: South | F22: 0297464461 | G22: Elena Haddad | H22: BRK007 | I22: 2011-01-18 | J22: Cosmetics and personal care
A23: IMP00018 | B23: T100119 | C23: Eastern Electronics & Sons | D23: 200 Harbour Road | E23: Coastal | F23: 0254068681 | G23: Nadia Sato | H23: BRK058 | I23: 2010-10-22 | J23: Cosmetics and personal care
A24: IMP00019 | B24: T100130 | C24: Royal Fruits Holdings Ltd | D24: 313 Market Street | E24: South | F24: 0269581004 | G24: Daniel Fernandes | H24: BRK011 | I24: 2022-05-23 | J24: Vehicles and parts
A25: IMP00020 | B25: T100134 | C25: Central Commercial Enterprises | D25: 218 Industrial Estate | E25: East | F25: 0945440269 | G25: Priya Patel | H25: BRK051 | I25: 2017-03-04 | J25: Tobacco and beverages
A26: IMP00021 | B26: T100144 | C26: Crown Textiles & Sons | D26: 242 Station Road | E26: West | F26: 0806964313 | G26: Joseph Tanaka | H26: BRK009 | I26: 2024-04-19 | J26: Pharmaceuticals
A27: IMP00022 | B27: T100152 | C27: Crown Glow Group Ltd | D27: 256 Market Street | E27: West | F27: 0980794230 | G27: Aisha Patel | H27: BRK037 | I27: 2021-02-27 | J27: Tobacco and beverages
... A31: IMP00026 | B31: T100177 | C31: Aldergate Supply Co., Ltd | D31: 153 Harbour Road | E31: South | F31: 0229299704 | G31: Omar Haddad | H31: BRK001 | I31: 2018-03-05 | J31: Vehicles and parts
A32: IMP00027 | C32: Sunrise Steel Limited | D32: 274 Riverside | E32: Capital | F32: 0819529945 | G32: Samuel Mahmood | H32: BRK019 | I32: 2014-09-04 | J32: Tobacco and beverages
A33: IMP00028 | B33: T100193 | C33: Inverness Agro Co. | D33: 206 Bazaar Lane | E33: Capital | F33: 0580341553 | G33: Daniel Mahmood | H33: BRK021 | I33: 2009-02-04 | J33: Fuel and chemicals
A34: IMP00029 | B34: T100201 | C34: Global Glow Ltd | D34: 338 Garden Lane | E34: East | F34: 0510129904 | G34: Samuel Patel | H34: BRK061 | I34: 2012-07-01 | J34: Food importers
A35: IMP00030 | B35: T100208 | C35: Evergreen Pack Partners Ltd | D35: 267 Riverside | E35: Coastal | F35: 0502506634 | G35: Samuel Okafor | H35: BRK021 | I35: 2015-08-17 | J35: Cosmetics and personal care
A36: IMP00031 | B36: T100211 | C36: Metro Living Partners Ltd | D36: 381 Temple Street | E36: South | F36: 0986965771 | G36: Daniel Ibrahim | H36: BRK026 | I36: 2010-02-26 | J36: Furniture and household
A37: IMP00032 | B37: T100219 | C37: Ashcombe Motors Co. | D37: 90 Airport Road | E37: East | F37: 0611073084 | G37: Omar Rahman | H37: BRK028 | I37: 2021-10-24 | J37: Machinery
A38: IMP00033 | B38: T100225 | C38: Global Agro International Ltd | D38: 260 Harbour Road | E38: Capital | F38: 0531652277 | G38: Amina Mensah | H38: BRK019 | I38: 2020-12-03 | J38: General trading
A39: IMP00034 | B39: T100236 | C39: Arden Supply Holdings Ltd | D39: 235 Mill Road | E39: North | F39: 0516341289 | G39: Grace Tanaka | H39: BRK042 | I39: 2014-09-23 | J39: Medical devices
A40: IMP00035 | B40: T100242 | C40: Metro Fruits Co. | D40: 6 Market Street | E40: Coastal | F40: 0581524750 | G40: Omar Sato | H40: BRK070 | I40: 2012-11-25 | J40: Cosmetics and personal care
A41: IMP00036 | B41: T100251 | C41: Horizon Glow Co., Ltd | D41: 354 Garden Lane | E41: Capital | F41: 0719900946 | G41: Somchai Chen | H41: BRK066 | I41: 2009-06-02 | J41: Machinery
A42: IMP00037 | B42: T100257 | C42: Carrick Agro & Sons | D42: 320 Temple Street | E42: East | F42: 0506676501 | G42: Aisha Al-Sayed | H42: BRK074 | I42: 2014-03-09 | J42: Steel and construction
A43: IMP00038 | B43: T100260 | C43: Prescott Steel Holdings Ltd | D43: 228 Industrial Estate | E43: North | F43: 0697360622 | G43: Tomas Mensah | H43: BRK014 | I43: 2019-12-02 | J43: Pharmaceuticals
A44: IMP00039 | B44: T100272 | C44: Central Imports Partners Ltd | D44: 294 Station Road | E44: East | F44: 0407340201 | G44: Ravi Bauer | H44: BRK054 | I44: 2008-08-30 | J44: Fuel and chemicals
... A57: IMP00052 | B57: T100360 | C57: Inverness Pack Limited | D57: 324 Industrial Estate | E57: Capital | F57: 0362842634 | G57: Somchai Tanaka | H57: BRK004 | I57: 2021-11-29 | J57: Tobacco and beverages
...

Sheet Consignees
A1: The consignee register · 2,002 parties goods are delivered to, as customs holds them
A4: consignee | B4: name | C4: address | D4: district | E4: importer | F4: tax number
A5: C00001 | B5: Metro Trading Co., Ltd | C5: 369 Airport Road | D5: North | E5: IMP00001 | F5: T100004
A6: C00002 | B6: Prescott Imports Group Ltd | C6: 102 Temple Street | D6: East | E6: IMP00002 | F6: T100013
A7: C00003 | B7: Saffron Trading & Sons | C7: 53 Garden Lane | D7: Capital | E7: IMP00003 | F7: T100016
A8: C00004 | B8: Harmony Fruits Co., Ltd | C8: 297 Airport Road | D8: North | E8: IMP00004 | F8: T100025
A9: C00005 | B9: Central Foods Limited | C9: 24 Harbour Road | D9: East | E9: IMP00005 | F9: T100033
A10: C00006 | B10: Saffron Textiles Co. | C10: 8 Mill Road | D10: North | E10: IMP00006 | F10: T100033
A11: C00007 | B11: Silk Road Enterprises Partners Ltd | C11: 241 Bazaar Lane | D11: Capital | E11: IMP00007
A12: C00008 | B12: Twin Rivers Textiles & Sons | C12: 179 Harbour Road | D12: South | E12: IMP00008 | F12: T100052
A13: C00009 | B13: Green Valley Imports Group Ltd | C13: 16 Industrial Estate | D13: West | E13: IMP00009 | F13: T100056
A14: C00010 | B14: Aldergate Trading Co. | C14: 71 Bazaar Lane | D14: Capital | E14: IMP00010 | F14: T800064
A15: C00011 | B15: Silk Road Steel Co. | C15: 346 Market Street | D15: North | E15: IMP00011 | F15: T100070
A16: C00012 | B16: Harmony Trading & Sons | C16: 199 Bazaar Lane | D16: North | E16: IMP00012 | F16: T100082
A17: C00013 | B17: Twin Rivers Glow International Ltd | C17: 399 Temple Street | D17: West | E17: IMP00013 | F17: T100090
A18: C00014 | B18: Silk Road Industries Co. | C18: 23 Airport Road | D18: East | E18: IMP00014 | F18: T100097
A19: C00015 | B19: Silver Logistics Co., Ltd | C19: 239 Airport Road | D19: Capital | E19: IMP00015 | F19: T100104
A20: C00016 | B20: Saffron Electronics International Ltd | C20: 180 Garden Lane | D20: North | E20: IMP00016 | F20: T100105
A21: C00017 | B21: Lotus Supply Partners Ltd | C21: 165 Airport Road | D21: South | E21: IMP00017 | F21: T100116
A22: C00018 | B22: Eastern Electronics & Sons | C22: 200 Harbour Road | D22: Coastal | E22: IMP00018 | F22: T100119
A23: C00019 | B23: Royal Fruits Holdings Ltd | C23: 313 Market Street | D23: South | E23: IMP00019 | F23: T100130
... A30: C00026 | B30: Aldergate Supply Co., Ltd | C30: 153 Harbour Road | D30: South | E30: IMP00026 | F30: T100177
A31: C00027 | B31: Sunrise Steel Limited | C31: 274 Riverside | D31: Capital | E31: IMP00027
A32: C00028 | B32: Inverness Agro Co. | C32: 206 Bazaar Lane | D32: Capital | E32: IMP00028 | F32: T100193
A33: C00029 | B33: Global Glow Ltd | C33: 338 Garden Lane | D33: East | E33: IMP00029 | F33: T100201
A34: C00030 | B34: Evergreen Pack Partners Ltd | C34: 267 Riverside | D34: Coastal | E34: IMP00030 | F34: T100208
A35: C00031 | B35: Metro Living Partners Ltd | C35: 381 Temple Street | D35: South | E35: IMP00031 | F35: T100211
A36: C00032 | B36: Ashcombe Motors Co. | C36: 90 Airport Road | D36: East | E36: IMP00032 | F36: T100219
A37: C00033 | B37: Global Agro International Ltd | C37: 260 Harbour Road | D37: Capital | E37: IMP00033 | F37: T100225
A38: C00034 | B38: Arden Supply Holdings Ltd | C38: 235 Mill Road | D38: North | E38: IMP00034 | F38: T100236
A39: C00035 | B39: Metro Fruits Co. | C39: 6 Market Street | D39: Coastal | E39: IMP00035 | F39: T100242
A40: C00036 | B40: Horizon Glow Co., Ltd | C40: 354 Garden Lane | D40: Capital | E40: IMP00036 | F40: T100251
A41: C00037 | B41: Carrick Agro & Sons | C41: 320 Temple Street | D41: East | E41: IMP00037 | F41: T100257
A42: C00038 | B42: Prescott Steel Holdings Ltd | C42: 228 Industrial Estate | D42: North | E42: IMP00038 | F42: T100260
A43: C00039 | B43: Central Imports Partners Ltd | C43: 294 Station Road | D43: East | E43: IMP00039 | F43: T100272
... A56: C00052 | B56: Inverness Pack Limited | C56: 324 Industrial Estate | D56: Capital | E56: IMP00052 | F56: T100360
A57: C00053 | B57: Twin Rivers Agro Group Ltd | C57: 180 Temple Street | D57: Capital | E57: IMP00053
A58: C00054 | B58: Eastern Pack Enterprises | C58: 95 Harbour Road | D58: South | E58: IMP00054 | F58: T100374
A59: C00055 | B59: Aldergate Steel Group Ltd | C59: 321 Market Street | D59: West | E59: IMP00055 | F59: T100381
A60: C00056 | B60: Inverness Industries Group Ltd | C60: 56 Garden Lane | D60: South | E60: IMP00056 | F60: T100388
...

Sheet Lines 12m
A1: The declaration lines that bear VAT, months 25 to 36, under the 25 tax numbers (and the lines of the five importers with no number)
A2: 12,320 lines, as exported. Lines that bear VAT: home use or release from a warehouse. A blank tax number means the declaration carried none.
A4: line | B4: date | C4: month | D4: importer | E4: tax number used to clear | F4: regime | G4: customs value (LCU) | H4: import VAT paid (LCU)
A5: L0171734 | B5: 2025-10-25 | C5: 25 | D5: IMP00005 | E5: T100033 | F5: home_use | G5: 1999563.4 | H5: 199956.34
A6: L0247648 | B6: 2026-09-18 | C6: 36 | D6: IMP00005 | E6: T100033 | F6: home_use | G6: 4314546.3 | H6: 474600.09
A7: L0236106 | B7: 2026-07-25 | C7: 34 | D7: IMP00006 | E7: T100033 | F7: home_use | G7: 2729997.3 | H7: 354899.65
A8: L0240642 | B8: 2026-08-16 | C8: 35 | D8: IMP00006 | E8: T100033 | F8: home_use | G8: 2091558.9 | H8: 271902.65
A9: L0166737 | B9: 2025-10-02 | C9: 25 | D9: IMP00095 | E9: T100033 | F9: home_use | G9: 947982.4 | H9: 118497.8
A10: L0166961 | B10: 2025-10-03 | C10: 25 | D10: IMP00095 | E10: T100033 | F10: home_use | G10: 784222.67 | H10: 98027.83
A11: L0169099 | B11: 2025-10-13 | C11: 25 | D11: IMP00095 | E11: T100033 | F11: home_use | G11: 81699.61 | H11: 8578.46
A12: L0170649 | B12: 2025-10-20 | C12: 25 | D12: IMP00095 | E12: T100033 | F12: home_use | G12: 501484.92 | H12: 65193.04
A13: L0173037 | B13: 2025-11-03 | C13: 26 | D13: IMP00095 | E13: T100033 | F13: home_use | G13: 908907.54 | H13: 106342.18
A14: L0184043 | B14: 2025-12-23 | C14: 27 | D14: IMP00095 | E14: T100033 | F14: home_use | G14: 1660461.2 | H14: 215859.95
A15: L0184294 | B15: 2025-12-24 | C15: 27 | D15: IMP00095 | E15: T100033 | F15: home_use | G15: 3006136.7 | H15: 375767.08
A16: L0184748 | B16: 2025-12-26 | C16: 27 | D16: IMP00095 | E16: T100033 | F16: home_use | G16: 532623.14 | H16: 69241.01
... A11318: L0250082 | B11318: 2026-09-28 | C11318: 36 | D11318: IMP01310 | E11318: T109167 | F11318: home_use | G11318: 1384760.8 | H11318: 138476.08
A11319: L0170213 | B11319: 2025-10-18 | C11319: 25 | D11319: IMP00147 | F11319: home_use | G11319: 3057472 | H11319: 305747.19
A11320: L0170459 | B11320: 2025-10-19 | C11320: 25 | D11320: IMP00147 | F11320: home_use | G11320: 2094467.4 | H11320: 209446.74
A11321: L0171537 | B11321: 2025-10-24 | C11321: 25 | D11321: IMP00147 | F11321: home_use | G11321: 1919281.7 | H11321: 191928.17
A11322: L0172800 | B11322: 2025-11-02 | C11322: 26 | D11322: IMP00147 | F11322: home_use | G11322: 2100944.3 | H11322: 210094.43
A11323: L0178920 | B11323: 2025-12-01 | C11323: 27 | D11323: IMP00147 | F11323: home_use | G11323: 3169131.7 | H11323: 316913.17
A11324: L0182007 | B11324: 2025-12-14 | C11324: 27 | D11324: IMP00147 | F11324: home_use | G11324: 822304.89 | H11324: 82230.49
A11325: L0186449 | B11325: 2026-01-05 | C11325: 28 | D11325: IMP00147 | F11325: home_use | G11325: 9906968.8 | H11325: 990696.88
A11326: L0193861 | B11326: 2026-02-06 | C11326: 29 | D11326: IMP00147 | F11326: home_use | G11326: 2132524.4 | H11326: 213252.44
A11327: L0195476 | B11327: 2026-02-12 | C11327: 29 | D11327: IMP00147 | F11327: home_use | G11327: 1783294 | H11327: 178329.4
A11328: L0196509 | B11328: 2026-02-16 | C11328: 29 | D11328: IMP00147 | F11328: home_use | G11328: 5102950.5 | H11328: 510295.05
A11329: L0196753 | B11329: 2026-02-17 | C11329: 29 | D11329: IMP00147 | F11329: home_use | G11329: 1009699.1 | H11329: 100969.91
A11330: L0203909 | B11330: 2026-03-16 | C11330: 30 | D11330: IMP00147 | F11330: home_use | G11330: 5120697.3 | H11330: 512069.73
... A12324: L0240849 | B12324: 2026-08-16 | C12324: 35 | D12324: IMP01481 | F12324: home_use | G12324: 3121163.4 | H12324: 333964.48

Sheet Returns
A1: The VAT returns · 24 monthly periods of every tax number the 25 importers can link to
A2: 600 returns, as the tax administration holds them. A return not filed carries blank amounts. Period number: 1 = 2024-10, 24 = 2026-09.
A4: tax ID | B4: period | C4: filed | D4: sales (LCU) | E4: purchases (LCU) | F4: import VAT deducted (LCU) | G4: period number
A5: T100033 | B5: 2024-10 | C5: 1 | D5: 59996 | E5: 239984 | F5: 0 | G5: 1
A6: T100033 | B6: 2024-11 | C6: 1 | D6: 66802 | E6: 267207 | F6: 0 | G6: 2
A7: T100033 | B7: 2024-12 | C7: 1 | D7: 47519 | E7: 190077 | F7: 0 | G7: 3
A8: T100033 | B8: 2025-01 | C8: 1 | D8: 302545 | E8: 2093577 | F8: 213366 | G8: 4
A9: T100033 | B9: 2025-02 | C9: 1 | D9: 51355 | E9: 205421 | F9: 0 | G9: 5
A10: T100033 | B10: 2025-03 | C10: 1 | D10: 55410 | E10: 221639 | F10: 0 | G10: 6
A11: T100033 | B11: 2025-04 | C11: 1 | D11: 84624 | E11: 338494 | F11: 0 | G11: 7
A12: T100033 | B12: 2025-05 | C12: 1 | D12: 103876 | E12: 415504 | F12: 0 | G12: 8
A13: T100033 | B13: 2025-06 | C13: 1 | D13: 124243 | E13: 496972 | F13: 0 | G13: 9
A14: T100033 | B14: 2025-07 | C14: 1 | D14: 88143 | E14: 352570 | F14: 0 | G14: 10
A15: T100033 | B15: 2025-08 | C15: 1 | D15: 70396 | E15: 281583 | F15: 0 | G15: 11
A16: T100033 | B16: 2025-09 | C16: 1 | D16: 52869 | E16: 211476 | F16: 0 | G16: 12
... A26: T100033 | B26: 2026-07 | C26: 1 | D26: 60447 | E26: 241789 | F26: 0 | G26: 22
A27: T100033 | B27: 2026-08 | C27: 0 | G27: 23
A28: T100033 | B28: 2026-09 | C28: 1 | D28: 692083 | E28: 4789146 | F28: 467491 | G28: 24
A29: T100070 | B29: 2024-10 | C29: 1 | D29: 306833 | E29: 1833154 | F29: 167257 | G29: 1
A30: T100070 | B30: 2024-11 | C30: 1 | D30: 2145197 | E30: 12816349 | F30: 1176098 | G30: 2
A31: T100070 | B31: 2024-12 | C31: 1 | D31: 1159576 | E31: 6927817 | F31: 629721 | G31: 3
A32: T100070 | B32: 2025-01 | C32: 1 | D32: 2558377 | E32: 15284868 | F32: 1402999 | G32: 4
A33: T100070 | B33: 2025-02 | C33: 1 | D33: 1332125 | E33: 7958697 | F33: 710312 | G33: 5
A34: T100070 | B34: 2025-03 | C34: 1 | D34: 960419 | E34: 5737963 | F34: 507189 | G34: 6
A35: T100070 | B35: 2025-04 | C35: 1 | D35: 2667385 | E35: 15936129 | F35: 1404238 | G35: 7
A36: T100070 | B36: 2025-05 | C36: 1 | D36: 97298 | E36: 581300 | F36: 60641 | G36: 8
A37: T100070 | B37: 2025-06 | C37: 1 | D37: 1372214 | E37: 8198210 | F37: 749700 | G37: 9
A38: T100070 | B38: 2025-07 | C38: 1 | D38: 1528694 | E38: 9133091 | F38: 844821 | G38: 10
A39: T100070 | B39: 2025-08 | C39: 1 | D39: 254227 | E39: 1518865 | F39: 135626 | G39: 11
... A42: T100070 | B42: 2025-11 | C42: 1 | D42: 661778 | E42: 3953752 | F42: 365132 | G42: 14
A43: T100070 | B43: 2025-12 | C43: 0 | G43: 15
A44: T100070 | B44: 2026-01 | C44: 1 | D44: 1121984 | E44: 6703224 | F44: 646984 | G44: 16
A45: T100070 | B45: 2026-02 | C45: 1 | D45: 1260182 | E45: 7528880 | F45: 685844 | G45: 17
A46: T100070 | B46: 2026-03 | C46: 1 | D46: 1202667 | E46: 7185261 | F46: 631723 | G46: 18
A47: T100070 | B47: 2026-04 | C47: 1 | D47: 3066290 | E47: 18319362 | F47: 1673697 | G47: 19
A48: T100070 | B48: 2026-05 | C48: 1 | D48: 1322678 | E48: 7902259 | F48: 695307 | G48: 20
A49: T100070 | B49: 2026-06 | C49: 1 | D49: 545344 | E49: 3258124 | F49: 296724 | G49: 21
A50: T100070 | B50: 2026-07 | C50: 1 | D50: 2967925 | E50: 17731687 | F50: 1634659 | G50: 22
A51: T100070 | B51: 2026-08 | C51: 1 | D51: 374374 | E51: 2236672 | F51: 205384 | G51: 23
A52: T100070 | B52: 2026-09 | C52: 1 | D52: 3866425 | E52: 23099720 | F52: 2119023 | G52: 24
...

Sheet Sectors
A1: The usual sales over imports of each sector (computed for you)
A2: The median of sales ÷ imports over the tax numbers both sides know that filed at least 10 of their last 12 returns. A median per sector: computed for you.
A4: sector | B4: usual sales ÷ imports | C4: numbers in the median
A5: Cosmetics and personal care | B5: 1.53 | C5: 85
A6: Electronics | B6: 1.388 | C6: 85
A7: Food importers | B7: 1.4272497 | C7: 81
A8: Fuel and chemicals | B8: 1.3431467 | C8: 86
A9: Furniture and household | B9: 1.5845 | C9: 80
A10: General trading | B10: 1.4655 | C10: 90
A11: Machinery | B11: 1.4245 | C11: 82
A12: Medical devices | B12: 1.5223379 | C12: 85
A13: Pharmaceuticals | B13: 1.5179904 | C13: 79
A14: Steel and construction | B14: 1.3897967 | C14: 78
A15: Textiles and apparel | B15: 1.6816275 | C15: 108
A16: Tobacco and beverages | B16: 1.4557721 | C16: 76
A17: Vehicles and parts | B17: 1.477 | C17: 99

Sheet S1 Match
A1: Sprint 1 · the 25 importers against the tax register: who is who
A2: Each row: the importer as customs holds it, and the tax register's best candidate (found by a search on name and address). The similarities are computed for you (purple): how alike the two strings are once cleaned. I17 is worked in grey.
A3: Your choice: 4B_lab.xlsx (sheet Match A) already has every confidence, and 4B_compute_worked.xlsx every formula.
A5: Step | B5: What to do | H5: Your answer | I5: Check | J5: Hint 1 · the tool (the full formula is on the Hints sheet)
A6: 1 | B6: Column K: does the tax number on the declaration exist in the tax register, as typed? "matched", "not in the register" or "blank". Then: how many rows match exactly? | I6: =IF(H6="","",IF(ISNUMBER(H6),IF(ABS(H6-_check!$B$2)<=0.5,"✓ matches","✗ not yet: see the hint"),"✗ not yet: see the hint")) | J6: COUNTIF counts the number in the register's tax ID column; IF turns the count into a word.
A7: 2 | B7: Column P: the match confidence: name × 0.4 + address × 0.3 + director × 0.3, a missing field left out and the weights rescaled over the fields present. Then: I17's confidence. | I7: =IF(H7="","",IF(ISNUMBER(H7),IF(ABS(H7-_check!$B$3)<=0.0006,"✓ matches","✗ not yet: see the hint"),"✗ not yet: see the hint")) | J7: N() turns an empty cell into 0; ISNUMBER says which fields are present, so the division rescales the weights.
A8: 3 | B8: Column Q: the class at the dial: exact when the number matched; validated probable at or above the link line; review between the two lines (a person decides); no link below. Then: how many rows wait in the review band? | I8: =IF(H8="","",IF(ISNUMBER(H8),IF(ABS(H8-_check!$B$4)<=0.5,"✓ matches","✗ not yet: see the hint"),"✗ not yet: see the hint")) | J8: IF inside IF, reading the two lines of the dial on the Parameters sheet.
A9: 4 | B9: Column R: the tax number on the tax side: the declared number when exact; the register's candidate when validated probable; nothing otherwise. Then: how many of the 25 rows have a tax number on the tax side? | I9: =IF(H9="","",IF(ISNUMBER(H9),IF(ABS(H9-_check!$B$5)<=0.5,"✓ matches","✗ not yet: see the hint"),"✗ not yet: see the hint")) | J9: IF on the class. Then count the cells of column R that are not empty.
A10: 5 | B10: Your class (column S): the class at the dial, unless your group decides a review-band pair after reading both records. Lock class and confidence for the 25 on the site. | J10: A wrong link costs more than a missed one: a letter to the wrong trader. Count the four classes; do not quote one match rate.
A15: ref | B15: importer (customs) | C15: tax number on the declaration | D15: address (customs) | E15: phone (customs) | F15: director (customs) | G15: best candidate: tax ID | H15: best candidate: legal name | I15: best candidate: address | J15: best candidate: director | K15: tax number as typed | L15: name similarity | M15: address similarity | N15: director similarity | O15: phone match (1/0) | P15: confidence | Q15: class at the dial | R15: tax number on the tax side | S15: your class
A16: I01 | B16: Ocean Electronics Co., Ltd | C16: T103629 | D16: 222 Mill Road | E16: 0817809823 | F16: Somchai Rahman | G16: T103629 | H16: Ocean Electronics Co., Ltd | I16: 222 Mill Road | J16: Somchai Rahman | L16: 1 | M16: 1 | N16: 1 | O16: 1
A17: I02 | B17: Phoenix Glow Limited | C17: T105264 | D17: 248 Industrial Estate | E17: 0496195011 | F17: Tomas Tanaka | G17: T105264 | H17: Phoenix Glow Limited | I17: 248 Industrial Estate | J17: Tomas Tanaka | L17: 1 | M17: 1 | N17: 1 | O17: 1
A18: I03 | B18: Delta Fruits Holdings Ltd | C18: T106240 | D18: 340 Industrial Estate | E18: 0459640429 | F18: Joseph Rahman | G18: T106240 | H18: Delta Fruits Holdings Ltd | I18: 340 INDUSTRIAL ESTATE | J18: Joseph Rahman | L18: 1 | M18: 1 | N18: 1 | O18: 1
A19: I04 | B19: Great Vellmoor Steel Enterprises | C19: T102376 | D19: 43 Riverside | E19: 0913214249 | F19: Elena Haddad | G19: T102376 | H19: Great Vellmoor Steel Enterprises | I19: 43 Riverside | J19: Elena Haddad | L19: 1 | M19: 1 | N19: 1 | O19: 1
A20: I05 | B20: Carrick Electronics Group Ltd | C20: T106987 | D20: 375 Industrial Estate | E20: 0719832200 | F20: Farid Okafor | G20: T106987 | H20: Carrick Electronics Group Ltd | I20: 375 Industrial Estate | J20: Farid Okafor | L20: 1 | M20: 1 | N20: 1 | O20: 1
A21: I06 | B21: Carrick Agro Enterprises | C21: T107258 | D21: 18 Market Street | E21: 0545102251 | F21: Kenji Haddad | G21: T107258 | H21: Carrick Agro Enterprises | I21: 18 Market Street | J21: Kenji Haddad | L21: 1 | M21: 1 | N21: 1 | O21: 1
A22: I07 | B22: Cobalt Mobile & Sons | C22: T102141 | D22: 314 Industrial Estate | E22: 0965281846 | F22: Elena Haddad | G22: T102141 | H22: COBALT MOBILE & SONS | I22: 314 Industrial Estate | J22: Elena Haddad | L22: 1 | M22: 1 | N22: 1 | O22: 1
A23: I08 | B23: Central Imports International Ltd | D23: 350 Garden Lane | E23: 0471338762 | F23: Kenji Haddad | G23: T102182 | H23: Central Enterprises Ltd | I23: 302 Bazaar Lane | J23: Daniel Nguyen-Lee | L23: 1 | M23: 0.615 | N23: 0.345 | O23: 0
A24: I09 | B24: Phoenix Imports Partners Ltd | D24: 171 Garden Lane | E24: 0887356246 | F24: Nadia Chen | G24: T514418 | H24: Phoenix Holdings International Ltd | I24: 118 Mill Road | J24: Ravi Patel | L24: 1 | M24: 0.417 | N24: 0.4 | O24: 0
A25: I10 | B25: Global Electronics International Ltd | C25: T103130 | D25: 296 Temple Street | E25: 0941933516 | F25: Amina Al-Sayed | G25: T103130 | H25: Global Electronics International Limited | J25: Amina Al-Sayed | L25: 1 | N25: 1 | O25: 1
A26: I11 | B26: Central Foods Limited | C26: T100033 | D26: 24 Harbour Road | E26: 0401520138 | F26: Farid Ibrahim | G26: T100033 | H26: Central Foods Limited | I26: 24 Harbour Road | J26: Farid Ibrahim | L26: 1 | M26: 1 | N26: 1 | O26: 1
A27: I12 | B27: Ocean Medical Co., Ltd | D27: 362 Temple Street | E27: 0482336020 | F27: Hassan Tanaka | G27: T109212 | H27: Ocean Enterprises Holdings Ltd | I27: 292 Temple Street | J27: Elena Rahman | L27: 1 | M27: 0.846 | N27: 0.32 | O27: 0
A28: I13 | B28: Central Enterprises Co. | D28: 191 Garden Lane | E28: 0946646378 | F28: Hassan Kowalski | G28: T110150 | H28: Central Textiles International Ltd | I28: Unit 28, 160 Garden Lane | J28: Grace Osei | L28: 1 | M28: 0.846 | N28: 0.4 | O28: 0
A29: I14 | B29: Royal Agro Co., Ltd | C29: T108692 | D29: 191 Bazaar Lane | E29: 0382439044 | F29: Somchai Silva | G29: T108692 | H29: Royal Agro Co., Ltd | I29: 191 BAZAAR LANE | J29: Somchai Silva | L29: 1 | M29: 1 | N29: 1 | O29: 1
A30: I15 | B30: Silk Road Steel Co. | C30: T100070 | D30: 346 Market Street | E30: 0519965779 | F30: Farid Haddad | G30: T100070 | H30: Silk Road Steel Co. | I30: 346 Market Street | J30: Farid Haddad | L30: 1 | M30: 1 | N30: 1 | O30: 1
A31: I16 | B31: Carrick Trading & Sons | C31: T107617 | D31: 172 Airport Road | E31: 0803847861 | F31: Ingrid Sato | G31: T107617 | H31: Carrick Trading & Sons | I31: 172 Airport Road | J31: Ingrid Sato | L31: 1 | M31: 1 | N31: 1 | O31: 1
A32: I17 | B32: Ocean Industries Holdings Ltd | D32: 323 Station Road | E32: 0924121092 | F32: Joseph Tanaka | G32: T106372 | H32: Ocean Industries Enterprises | I32: 275 Station Road | J32: Tomas Mensah | K32: =IF(C32="","blank",IF(COUNTIF('Tax register'!$A$5:$A$1803,C32)>0,"matched","not in the register")) | L32: 1 | M32: 0.857 | N32: 0.4 | O32: 0 | P32: =IF(COUNT(L32:N32)=0,0,(Parameters!$B$5*N(L32)+Parameters!$B$6*N(M32)+Parameters!$B$7*N(N32))/(Parameters!$B$5*ISNUMBER(L32)+Parameters!$B$6*ISNUMBER(M32)+Parameters!$B$7*ISNUMBER(N32))) | Q32: =IF(K32="matched","exact",IF(P32>=Parameters!$B$8,"validated probable",IF(P32>=Parameters!$B$9,"review","no link"))) | R32: =IF(S32="exact",C32,IF(S32="validated probable",G32,"")) | S32: =Q32
A33: I18 | B33: Arden Living Co. | C33: T107992 | D33: 144 Riverside | E33: 0894167333 | F33: Samuel Kowalski | G33: T107992 | H33: Arden Living Co. | I33: 144 Riverside | J33: Samuel Kowalski | L33: 1 | M33: 1 | N33: 1 | O33: 1
A34: I19 | B34: Pacific Living Co. | C34: T109167 | D34: 329 Riverside | E34: 0346234502 | F34: Aisha Reyes | G34: T109167 | H34: Pacific Living Co. | I34: 329 Riverside | J34: Aisha Reyes | L34: 1 | M34: 1 | N34: 1 | O34: 1
A35: I20 | B35: Ocean Trading International Ltd | C35: T103425 | D35: 115 Harbour Road | E35: 0731410108 | F35: Nadia Al-Sayed | G35: T103425 | H35: Ocean Trading International Ltd | I35: 115 Harbour Road | J35: Nadia Al-Sayed | L35: 1 | M35: 1 | N35: 1 | O35: 1
A36: I21 | B36: Metro Motors Co., Ltd | C36: T100440 | D36: 215 Bazaar Lane | E36: 0929915234 | F36: Ingrid Al-Sayed | G36: T100440 | H36: Metro Motors Co., Ltd | I36: 215 Bazaar Lane | J36: Ingrid Al-Sayed | L36: 1 | M36: 1 | N36: 1 | O36: 1
A37: I22 | B37: Metro Steel Partners Ltd | C37: T106477 | D37: 358 Market Street | E37: 0402667378 | F37: Amina Bauer | G37: T106477 | H37: Metro Steel Partners Ltd | I37: 358 Market Street | J37: Amina Bauer | L37: 1 | M37: 1 | N37: 1 | O37: 1
A38: I23 | B38: Aldergate Agro Holdings Ltd | C38: T104498 | D38: 340 Garden Lane | E38: 0612702458 | F38: Daniel Osei | G38: T104498 | H38: Aldergate Agro Holdings Ltd | I38: 340 Garden Lane | J38: Daniel Osei | L38: 1 | M38: 1 | N38: 1 | O38: 1
A39: I24 | B39: Pacific Enterprises Holdings Ltd | C39: T100466 | D39: 356 Station Road | E39: 0254736740 | F39: Farid Sato | G39: T100466 | H39: Pacific Enterprises Holdings Ltd | I39: 356 Station Road | J39: Farid Sato | L39: 1 | M39: 1 | N39: 1 | O39: 1
A40: I25 | B40: Arden Fruits Enterprises | C40: T102011 | D40: 360 Harbour Road | E40: 0225352118 | F40: Mei Okafor | G40: T102015 | H40: ARDEN FRUITS ENTERPRISES | I40: 360 Harbour Road | J40: Mei Okafor | L40: 1 | M40: 1 | N40: 1 | O40: 1
A42: The worked case, I17: no number on the declaration; the register's best candidate T106372 · name 1.00, address 0.857, director 0.40: 0.4 × 1.00 + 0.3 × 0.857 + 0.3 × 0.40 = 0.777, in the review band. A person reads both records before any letter.

Sheet S1 Track B
A1: Sprint 1 · Track B: a real register, and where to set the dial
A2: Left: the matching recipe's best candidate for each of 3,200 customs rows, with its score (computed for you). Middle: 300 pairs a clerk checked by hand (1 = the same trader, 0 = not). Rows by number only; no name is read aloud.
A5: customs row | B5: register row | C5: score | D5: band | F5: customs row | G5: register row | H5: label (1 = same) | I5: its score | K5: at the dial | L5: 0.5 | M5: 0.7 | N5: 0.9
A6: C00001 | B6: R01223 | C6: 1 | D6: exact | F6: C00018 | G6: R00507 | H6: 0 | I6: =VLOOKUP(F6,$A$6:$C$3205,3,FALSE) | K6: pairs at or above (all rows) | L6: =COUNTIF($C$6:$C$3205,">="&L$5)
A7: C00002 | B7: R00398 | C7: 1 | D7: exact | F7: C00020 | G7: R01739 | H7: 1 | I7: =VLOOKUP(F7,$A$6:$C$3205,3,FALSE) | K7: sample pairs at or above | L7: =COUNTIF($I$6:$I$305,">="&L$5)
A8: C00003 | B8: R02417 | C8: 1 | D8: exact | F8: C00028 | G8: R01517 | H8: 1 | I8: =VLOOKUP(F8,$A$6:$C$3205,3,FALSE) | K8: precision: true links ÷ sample pairs at or above | L8: =IFERROR(COUNTIFS($I$6:$I$305,">="&L$5,$H$6:$H$305,1)/L7,"")
A9: C00004 | B9: R01899 | C9: 1 | D9: exact | F9: C00031 | G9: R01600 | H9: 1 | I9: =VLOOKUP(F9,$A$6:$C$3205,3,FALSE) | K9: recall: true links at or above ÷ all true links | L9: =IFERROR(COUNTIFS($I$6:$I$305,">="&L$5,$H$6:$H$305,1)/COUNTIF($H$6:$H$305,1),"")
A10: C00005 | B10: R02666 | C10: 1 | D10: exact | F10: C00037 | G10: R02691 | H10: 1 | I10: =VLOOKUP(F10,$A$6:$C$3205,3,FALSE)
A11: C00006 | B11: R02060 | C11: 1 | D11: exact | F11: C00049 | G11: R00866 | H11: 1 | K11: checks (rows 6 to 9) | L11: =IF(COUNT($I$6:$I$305)<300,"",IF(L6="","",IF(ISNUMBER(L6),IF(ABS(L6-_check!$B$6)<=0.5,"✓","✗"),"✗"))) | M11: =IF(COUNT($I$6:$I$305)<300,"",IF(M6="","",IF(ISNUMBER(M6),IF(ABS(M6-_check!$B$7)<=0.5,"✓","✗"),"✗"))) | N11: =IF(COUNT($I$6:$I$305)<300,"",IF(N6="","",IF(ISNUMBER(N6),IF(ABS(N6-_check!$B$8)<=0.5,"✓","✗"),"✗")))
A12: C00007 | B12: R01228 | C12: 1 | D12: exact | F12: C00059 | G12: R00785 | H12: 1 | L12: =IF(COUNT($I$6:$I$305)<300,"",IF(L7="","",IF(ISNUMBER(L7),IF(ABS(L7-_check!$B$9)<=0.5,"✓","✗"),"✗"))) | M12: =IF(COUNT($I$6:$I$305)<300,"",IF(M7="","",IF(ISNUMBER(M7),IF(ABS(M7-_check!$B$10)<=0.5,"✓","✗"),"✗"))) | N12: =IF(COUNT($I$6:$I$305)<300,"",IF(N7="","",IF(ISNUMBER(N7),IF(ABS(N7-_check!$B$11)<=0.5,"✓","✗"),"✗")))
A13: C00008 | B13: R00709 | C13: 1 | D13: exact | F13: C00062 | G13: R02603 | H13: 1 | L13: =IF(COUNT($I$6:$I$305)<300,"",IF(L8="","",IF(ISNUMBER(L8),IF(ABS(L8-_check!$B$12)<=0.0006,"✓","✗"),"✗"))) | M13: =IF(COUNT($I$6:$I$305)<300,"",IF(M8="","",IF(ISNUMBER(M8),IF(ABS(M8-_check!$B$13)<=0.0006,"✓","✗"),"✗"))) | N13: =IF(COUNT($I$6:$I$305)<300,"",IF(N8="","",IF(ISNUMBER(N8),IF(ABS(N8-_check!$B$14)<=0.0006,"✓","✗"),"✗")))
A14: C00009 | B14: R01515 | C14: 0.4259 | D14: no match | F14: C00073 | G14: R00465 | H14: 1 | L14: =IF(COUNT($I$6:$I$305)<300,"",IF(L9="","",IF(ISNUMBER(L9),IF(ABS(L9-_check!$B$15)<=0.0006,"✓","✗"),"✗"))) | M14: =IF(COUNT($I$6:$I$305)<300,"",IF(M9="","",IF(ISNUMBER(M9),IF(ABS(M9-_check!$B$16)<=0.0006,"✓","✗"),"✗"))) | N14: =IF(COUNT($I$6:$I$305)<300,"",IF(N9="","",IF(ISNUMBER(N9),IF(ABS(N9-_check!$B$17)<=0.0006,"✓","✗"),"✗")))
A15: C00010 | B15: R00624 | C15: 0.6541 | D15: no match | F15: C00079 | G15: R01142 | H15: 1
A16: C00011 | B16: R00446 | C16: 1 | D16: exact | F16: C00102 | G16: R01427 | H16: 1 | K16: Read the trade-off: a strict dial (0.9) is almost always right and misses most true links; a loose one (0.5) finds them and sends letters to the wrong trader. The sample is 300 pairs: a precision of 87% on 200 pairs can be anything from about 81% to 91%.
A17: C00012 | B17: R01431 | C17: 1 | D17: exact | F17: C00113 | G17: R00350 | H17: 1
A18: C00013 | B18: R02150 | C18: 1 | D18: exact | F18: C00120 | G18: R01761 | H18: 1
A19: C00014 | B19: R01423 | C19: 1 | D19: exact | F19: C00122 | G19: R01080 | H19: 1
A20: C00015 | B20: R01242 | C20: 0.6541 | D20: no match | F20: C00140 | G20: R00812 | H20: 1
A21: C00016 | B21: R02239 | C21: 1 | D21: exact | F21: C00142 | G21: R02154 | H21: 1
A22: C00017 | B22: R01133 | C22: 0.6541 | D22: no match | F22: C00147 | G22: R02873 | H22: 1
A23: C00018 | B23: R00507 | C23: 0.2202 | D23: no match | F23: C00148 | G23: R02192 | H23: 1
A24: C00019 | B24: R02036 | C24: 1 | D24: exact | F24: C00169 | G24: R02168 | H24: 1
A25: C00020 | B25: R01739 | C25: 0.7718 | D25: review | F25: C00171 | G25: R01471 | H25: 1
A26: C00021 | B26: R02476 | C26: 1 | D26: exact | F26: C00174 | G26: R01045 | H26: 1
A27: C00022 | B27: R00487 | C27: 1 | D27: exact | F27: C00190 | G27: R01903 | H27: 1
A28: C00023 | B28: R01823 | C28: 1 | D28: exact | F28: C00192 | G28: R01868 | H28: 1
... A305: C00300 | B305: R02870 | C305: 1 | D305: exact | F305: C03177 | G305: R00007 | H305: 1
A306: C00301 | B306: R01894 | C306: 0.7718 | D306: review
A307: C00302 | B307: R02400 | C307: 0.6541 | D307: no match
A308: C00303 | B308: R00726 | C308: 0.6541 | D308: no match
A309: C00304 | B309: R00152 | C309: 1 | D309: exact
A310: C00305 | B310: R02105 | C310: 0.7718 | D310: review
A311: C00306 | B311: R01953 | C311: 0.7942 | D311: review
A312: C00307 | B312: R02188 | C312: 1 | D312: exact
A313: C00308 | B313: R00577 | C313: 1 | D313: exact
A314: C00309 | B314: R02629 | C314: 0.6541 | D314: no match
A315: C00310 | B315: R01469 | C315: 1 | D315: exact
A316: C00311 | B316: R00689 | C316: 0.7718 | D316: review
A317: C00312 | B317: R00787 | C317: 1 | D317: exact
... A3205: C03200 | B3205: R02031 | C3205: 0.6541 | D3205: no match

Sheet S2 Four lists
A1: Sprint 2 · follow one import through both administrations: four questions, four lists
A2: A trader goes on the list of the first question it fails: 1 not known to tax, 2 not filing, 3 import not in its books, 4 sells below what it imports, else consistent for now. I01 is worked in grey. Your class comes from S1 Match, column S.
A3: Your choice: 4B_lab.xlsx (sheet Lists) already has every number. The checks assume the classes at the dial; if your group linked a review-band pair, its row will differ, and that is your call.
A5: Step | B5: What to do | H5: Your answer | I5: Check | J5: Hint 1 · the tool (the full formula is on the Hints sheet)
A6: 1 | B6: Columns H and I: imports and import VAT paid over the last twelve months, adding up the lines that bear VAT under the tax number used to clear (Lines 12m). With no number, under the importer's own code. Then: the imports of the 25, added up. | I6: =IF(H6="","",IF(ISNUMBER(H6),IF(ABS(H6-_check!$B$18)<=1,"✓ matches","✗ not yet: see the hint"),"✗ not yet: see the hint")) | J6: SUMIFS on the Lines 12m sheet, by tax number; IF the number is blank, by importer code.
A7: 2 | B7: Columns J to M: on the tax side (column G), the returns filed of the last six, the import VAT deducted and the sales over twelve months, and booked = deducted ÷ paid. Then: how many of the 25 filed all six of their last six returns? | I7: =IF(H7="","",IF(ISNUMBER(H7),IF(ABS(H7-_check!$B$19)<=0.5,"✓ matches","✗ not yet: see the hint"),"✗ not yet: see the hint")) | J7: COUNTIFS on the Returns sheet: the tax ID, filed = 1, period number ≥ 19. SUMIFS for the amounts, period number ≥ 13.
A8: 3 | B8: Columns N and O: sales ÷ imports, and the sector's usual (Sectors sheet). Column P: the first question failed (1 to 5). Column Q: the VAT at stake. Then: how many importers fail question 2 (not filing)? | I8: =IF(H8="","",IF(ISNUMBER(H8),IF(ABS(H8-_check!$B$20)<=0.5,"✓ matches","✗ not yet: see the hint"),"✗ not yet: see the hint")) | J8: IF inside IF, in the order of the four questions. VAT at stake, 10%: lists 1-2, VAT × imports × (usual − 1); lists 3-4, VAT × (imports × usual − sales); never below 0.
A9: 4 | B9: Column R: list 4 ranked by VAT at stake. Column S: the list, cut at the capacity. Then: the VAT at stake within capacity (lists 1 to 3, and list 4 up to the capacity). | I9: =IF(H9="","",IF(ISNUMBER(H9),IF(ABS(H9-_check!$B$21)<=1000,"✓ matches","✗ not yet: see the hint"),"✗ not yet: see the hint")) | J9: COUNTIFS counts the list-4 importers with more at stake. The summary table below adds up by list.
A10: 5 | B10: Columns T and U: the lead and the action for each list. Lock list, reason, lead and VAT at stake for the 25 on the site. | J10: List 1: tax, registration letter. List 2: tax, stop-filer letter. List 3: joint, ask for the books. List 4: tax with the customs data, desk audit, largest first.
A16: ref | B16: importer code | C16: tax number on the declaration | D16: importer (customs) | E16: sector | F16: your class (S1 Match) | G16: tax number on the tax side | H16: imports, 12 months (LCU) | I16: import VAT paid, 12 months (LCU) | J16: returns filed of the last 6 | K16: import VAT deducted, 12 months (LCU) | L16: booked (deducted ÷ paid) | M16: sales, 12 months (LCU) | N16: sales ÷ imports | O16: sector usual | P16: first question failed (1-5) | Q16: VAT at stake (LCU) | R16: rank on list 4 | S16: list | T16: check | U16: lead | V16: action
A17: I01 | B17: IMP00519 | C17: T103629 | D17: Ocean Electronics Co., Ltd | E17: Fuel and chemicals | F17: =IF('S1 Match'!S16="","",'S1 Match'!S16) | G17: =IF('S1 Match'!R16="","",'S1 Match'!R16) | H17: =IF(C17="",SUMIFS('Lines 12m'!$G$5:$G$12324,'Lines 12m'!$D$5:$D$12324,B17),SUMIFS('Lines 12m'!$G$5:$G$12324,'Lines 12m'!$E$5:$E$12324,C17)) | I17: =IF(C17="",SUMIFS('Lines 12m'!$H$5:$H$12324,'Lines 12m'!$D$5:$D$12324,B17),SUMIFS('Lines 12m'!$H$5:$H$12324,'Lines 12m'!$E$5:$E$12324,C17)) | J17: =IF(G17="","",COUNTIFS(Returns!$A$5:$A$604,G17,Returns!$C$5:$C$604,1,Returns!$G$5:$G$604,">="&Parameters!$B$11)) | K17: =IF(G17="","",SUMIFS(Returns!$F$5:$F$604,Returns!$A$5:$A$604,G17,Returns!$G$5:$G$604,">="&Parameters!$B$12)) | L17: =IF(OR(G17="",N(I17)=0),"",K17/I17) | M17: =IF(G17="","",SUMIFS(Returns!$D$5:$D$604,Returns!$A$5:$A$604,G17,Returns!$G$5:$G$604,">="&Parameters!$B$12)) | N17: =IF(OR(M17="",N(H17)=0),"",M17/H17) | O17: =IFERROR(VLOOKUP(E17,Sectors!$A$5:$B$17,2,FALSE),"") | P17: =IF(G17="",1,IF(J17<Parameters!$B$14,2,IF(L17<Parameters!$B$15,3,IF(N17<Parameters!$B$16,4,5)))) | Q17: =IF(P17<=2,MAX(0,Parameters!$B$10*H17*(O17-1)),IF(P17<=4,MAX(0,Parameters!$B$10*(H17*O17-M17)),0)) | R17: =IF(P17=4,COUNTIFS($P$17:$P$41,4,$Q$17:$Q$41,">"&Q17)+1,"") | S17: =IF(P17=4,IF(R17<=Parameters!$B$17,"4 desk audit, ranked by VAT at stake","4b below imports, beyond capacity"),CHOOSE(P17,"1 not known to tax","2 not filing","3 import not booked","","5 consistent for now")) | T17: =IF(OR(H17="",S17="",F17=""),"",IFERROR(IF(AND(ABS(H17-_check!$B$22)<=1,J17=_check!$B$23,ABS(N17-_check!$B$24)<=0.0006),"✓","✗"),"✗"))
A18: I02 | B18: IMP00753 | C18: T105264 | D18: Phoenix Glow Limited | E18: Textiles and apparel | F18: =IF('S1 Match'!S17="","",'S1 Match'!S17) | G18: =IF('S1 Match'!R17="","",'S1 Match'!R17) | T18: =IF(OR(H18="",S18="",F18=""),"",IFERROR(IF(AND(ABS(H18-_check!$B$25)<=1,J18=_check!$B$26,ABS(N18-_check!$B$27)<=0.0006),"✓","✗"),"✗"))
A19: I03 | B19: IMP00892 | C19: T106240 | D19: Delta Fruits Holdings Ltd | E19: General trading | F19: =IF('S1 Match'!S18="","",'S1 Match'!S18) | G19: =IF('S1 Match'!R18="","",'S1 Match'!R18) | T19: =IF(OR(H19="",S19="",F19=""),"",IFERROR(IF(AND(ABS(H19-_check!$B$28)<=1,J19=_check!$B$29,ABS(N19-_check!$B$30)<=0.0006),"✓","✗"),"✗"))
A20: I04 | B20: IMP00340 | C20: T102376 | D20: Great Vellmoor Steel Enterprises | E20: Fuel and chemicals | F20: =IF('S1 Match'!S19="","",'S1 Match'!S19) | G20: =IF('S1 Match'!R19="","",'S1 Match'!R19) | T20: =IF(OR(H20="",S20="",F20=""),"",IFERROR(IF(AND(ABS(H20-_check!$B$31)<=1,J20=_check!$B$32,ABS(N20-_check!$B$33)<=0.0006),"✓","✗"),"✗"))
A21: I05 | B21: IMP00999 | C21: T106987 | D21: Carrick Electronics Group Ltd | E21: Electronics | F21: =IF('S1 Match'!S20="","",'S1 Match'!S20) | G21: =IF('S1 Match'!R20="","",'S1 Match'!R20) | T21: =IF(OR(H21="",S21="",F21=""),"",IFERROR(IF(AND(ABS(H21-_check!$B$34)<=1,J21=_check!$B$35,ABS(N21-_check!$B$36)<=0.0006),"✓","✗"),"✗"))
A22: I06 | B22: IMP01037 | C22: T107258 | D22: Carrick Agro Enterprises | E22: Medical devices | F22: =IF('S1 Match'!S21="","",'S1 Match'!S21) | G22: =IF('S1 Match'!R21="","",'S1 Match'!R21) | T22: =IF(OR(H22="",S22="",F22=""),"",IFERROR(IF(AND(ABS(H22-_check!$B$37)<=1,J22=_check!$B$38,ABS(N22-_check!$B$39)<=0.0006),"✓","✗"),"✗"))
A23: I07 | B23: IMP00306 | C23: T102141 | D23: Cobalt Mobile & Sons | E23: Furniture and household | F23: =IF('S1 Match'!S22="","",'S1 Match'!S22) | G23: =IF('S1 Match'!R22="","",'S1 Match'!R22) | T23: =IF(OR(H23="",S23="",F23=""),"",IFERROR(IF(AND(ABS(H23-_check!$B$40)<=1,J23=_check!$B$41,ABS(N23-_check!$B$42)<=0.0006),"✓","✗"),"✗"))
A24: I08 | B24: IMP00147 | D24: Central Imports International Ltd | E24: Pharmaceuticals | F24: =IF('S1 Match'!S23="","",'S1 Match'!S23) | G24: =IF('S1 Match'!R23="","",'S1 Match'!R23) | T24: =IF(OR(H24="",S24="",F24=""),"",IFERROR(IF(AND(ABS(H24-_check!$B$43)<=1),"✓","✗"),"✗"))
A25: I09 | B25: IMP00721 | D25: Phoenix Imports Partners Ltd | E25: General trading | F25: =IF('S1 Match'!S24="","",'S1 Match'!S24) | G25: =IF('S1 Match'!R24="","",'S1 Match'!R24) | T25: =IF(OR(H25="",S25="",F25=""),"",IFERROR(IF(AND(ABS(H25-_check!$B$44)<=1),"✓","✗"),"✗"))
A26: I10 | B26: IMP00448 | C26: T103130 | D26: Global Electronics International Ltd | E26: Fuel and chemicals | F26: =IF('S1 Match'!S25="","",'S1 Match'!S25) | G26: =IF('S1 Match'!R25="","",'S1 Match'!R25) | T26: =IF(OR(H26="",S26="",F26=""),"",IFERROR(IF(AND(ABS(H26-_check!$B$45)<=1,J26=_check!$B$46,ABS(N26-_check!$B$47)<=0.0006),"✓","✗"),"✗"))
A27: I11 | B27: IMP00005 | C27: T100033 | D27: Central Foods Limited | E27: Steel and construction | F27: =IF('S1 Match'!S26="","",'S1 Match'!S26) | G27: =IF('S1 Match'!R26="","",'S1 Match'!R26) | T27: =IF(OR(H27="",S27="",F27=""),"",IFERROR(IF(AND(ABS(H27-_check!$B$48)<=1,J27=_check!$B$49,ABS(N27-_check!$B$50)<=0.0006),"✓","✗"),"✗"))
A28: I12 | B28: IMP00156 | D28: Ocean Medical Co., Ltd | E28: Tobacco and beverages | F28: =IF('S1 Match'!S27="","",'S1 Match'!S27) | G28: =IF('S1 Match'!R27="","",'S1 Match'!R27) | T28: =IF(OR(H28="",S28="",F28=""),"",IFERROR(IF(AND(ABS(H28-_check!$B$51)<=1),"✓","✗"),"✗"))
A29: I13 | B29: IMP00950 | D29: Central Enterprises Co. | E29: Tobacco and beverages | F29: =IF('S1 Match'!S28="","",'S1 Match'!S28) | G29: =IF('S1 Match'!R28="","",'S1 Match'!R28) | T29: =IF(OR(H29="",S29="",F29=""),"",IFERROR(IF(AND(ABS(H29-_check!$B$52)<=1),"✓","✗"),"✗"))
A30: I14 | B30: IMP01242 | C30: T108692 | D30: Royal Agro Co., Ltd | E30: Electronics | F30: =IF('S1 Match'!S29="","",'S1 Match'!S29) | G30: =IF('S1 Match'!R29="","",'S1 Match'!R29) | T30: =IF(OR(H30="",S30="",F30=""),"",IFERROR(IF(AND(ABS(H30-_check!$B$53)<=1,J30=_check!$B$54,ABS(N30-_check!$B$55)<=0.0006),"✓","✗"),"✗"))
A31: I15 | B31: IMP00011 | C31: T100070 | D31: Silk Road Steel Co. | E31: Pharmaceuticals | F31: =IF('S1 Match'!S30="","",'S1 Match'!S30) | G31: =IF('S1 Match'!R30="","",'S1 Match'!R30) | T31: =IF(OR(H31="",S31="",F31=""),"",IFERROR(IF(AND(ABS(H31-_check!$B$56)<=1,J31=_check!$B$57,ABS(N31-_check!$B$58)<=0.0006),"✓","✗"),"✗"))
A32: I16 | B32: IMP01089 | C32: T107617 | D32: Carrick Trading & Sons | E32: Machinery | F32: =IF('S1 Match'!S31="","",'S1 Match'!S31) | G32: =IF('S1 Match'!R31="","",'S1 Match'!R31) | T32: =IF(OR(H32="",S32="",F32=""),"",IFERROR(IF(AND(ABS(H32-_check!$B$59)<=1,J32=_check!$B$60,ABS(N32-_check!$B$61)<=0.0006),"✓","✗"),"✗"))
A33: I17 | B33: IMP01481 | D33: Ocean Industries Holdings Ltd | E33: Steel and construction | F33: =IF('S1 Match'!S32="","",'S1 Match'!S32) | G33: =IF('S1 Match'!R32="","",'S1 Match'!R32) | T33: =IF(OR(H33="",S33="",F33=""),"",IFERROR(IF(AND(ABS(H33-_check!$B$62)<=1),"✓","✗"),"✗"))
A34: I18 | B34: IMP01142 | C34: T107992 | D34: Arden Living Co. | E34: Fuel and chemicals | F34: =IF('S1 Match'!S33="","",'S1 Match'!S33) | G34: =IF('S1 Match'!R33="","",'S1 Match'!R33) | T34: =IF(OR(H34="",S34="",F34=""),"",IFERROR(IF(AND(ABS(H34-_check!$B$63)<=1,J34=_check!$B$64,ABS(N34-_check!$B$65)<=0.0006),"✓","✗"),"✗"))
A35: I19 | B35: IMP01310 | C35: T109167 | D35: Pacific Living Co. | E35: Textiles and apparel | F35: =IF('S1 Match'!S34="","",'S1 Match'!S34) | G35: =IF('S1 Match'!R34="","",'S1 Match'!R34) | T35: =IF(OR(H35="",S35="",F35=""),"",IFERROR(IF(AND(ABS(H35-_check!$B$66)<=1,J35=_check!$B$67,ABS(N35-_check!$B$68)<=0.0006),"✓","✗"),"✗"))
A36: I20 | B36: IMP00490 | C36: T103425 | D36: Ocean Trading International Ltd | E36: Machinery | F36: =IF('S1 Match'!S35="","",'S1 Match'!S35) | G36: =IF('S1 Match'!R35="","",'S1 Match'!R35) | T36: =IF(OR(H36="",S36="",F36=""),"",IFERROR(IF(AND(ABS(H36-_check!$B$69)<=1,J36=_check!$B$70,ABS(N36-_check!$B$71)<=0.0006),"✓","✗"),"✗"))
