Workbook

Sheet Start here
A1: Breakout 4B · compute it yourself · WORKED VERSION (every formula filled in)
A3: Each sprint has a worksheet where your group computes its numbers with ordinary Excel tools, from the raw rows both administrations hold (the customs registers and declaration lines, the tax register, the VAT returns, the tax audits), and records its findings. 4B_lab.xlsx shows every number already computed; here you learn how they are made. When your number is right, the Check cell turns green.
A4: Three kinds of sheets. Worksheets (S1 Match to S4 Tax feeds customs): your steps, your answers and their checks; their raw columns are rows copied from the raw sheets (the line above each block says which). Raw sheets (Customs importers, Consignees, Brokers, Tax register, VAT returns, VAT filings, Declarations, Controls, Tax audits): the rows of workshop_extract.xlsx unchanged, under the extract's headers (row 3) and codes (row 4); the first line of each says how to rebuild it from the extract and how many rows it has, the second which of the extract's columns it carries. Tax audits is CSV only (tax_audits.csv). Helper sheets (Similarities, Sectors): computed for you, because they need a script; the first lines say how.
A5: Colours: yellow = you type here (a number or a formula). Grey = given or worked for you (I01 and its number T103629 through every sheet; I17 on S1 Match too). Purple = computed for you (a helper: string similarity, a model score, a median per sector; the Fields sheet and the sheet's first lines say how). White = as recorded. Navy = column names. Every threshold sits on the Parameters sheet: change one there and every formula follows. A formula always starts with = . To copy a formula down a whole column: click the cell, then double-click the small square at its bottom-right corner.
A6: Step 0, for confident groups: open workshop_extract.xlsx, rebuild a raw sheet (or a worksheet's block) with the filter its first line gives, and compare the row count; on S2 Four lists, type the count of the lines block in AD6. Stuck? Hint 1 is beside each step. Hint 2, the full formula, is on the Hints sheet and on the site. The coach (coach-4b) helps one step at a time. 4B_compute_worked.xlsx shows every formula filled in.
A8: When | B8: Sheet | D8: What you compute
A9: Sprint 1 | B9: S1 Match | D9: The 25 importers against the tax register: the exact join on the tax number, the candidate's record and the phone match (joins on the Tax register), the match confidence from the similarities (computed for you), the class at the dial. I17 is worked.
A10: Sprint 1 | B10: S1 Track B | D10: A real register: precision and recall on the labelled sample at three settings of the dial.
A11: Sprint 2 | B11: S2 Four lists | D11: From the raw lines and returns: the month of each line and the period number of each return, then imports and import VAT paid, returns filed, import VAT deducted, sales; the four questions in order; VAT at stake; list 4 ranked and cut at the capacity. I01 is worked.
A12: Sprint 3 | B12: S3 Network | D12: From the customs registers: what each tax number serves (names, consignees, addresses, brokers, the first two from a block of the register's rows), the rule, and what the tax register says about its director.
A13: Sprint 4 | B13: S4 Tax feeds customs | D13: With the tax audit file: does a tax adjustment found at random point to customs findings? Each line's control result (Controls), the customs hit rate with and without a tax adjustment, and the lift.
A14: Thresholds | B14: Parameters | D14: Every threshold of the breakout: the weights and the dial, the VAT rate, the periods and months of the last six and twelve, the four questions, the capacity, the network rule, and where the months and the VAT periods start.
A15: Helpers | B15: Similarities, Sectors | D15: Computed for you (purple), each with one line on how.
A16: Raw sheets | B16: Customs importers, Consignees, Brokers, Tax register, VAT returns, VAT filings, Declarations, Controls, Tax audits | D16: Customs importers: 1,502 rows; Consignees: 2,002 rows; Brokers: 80 rows; Tax register: 1,799 rows; VAT returns: 600 rows; VAT filings: 600 rows; Declarations: 13,517 rows; Controls: 1,414 rows; Tax audits: 284 rows. Each first line says how to rebuild it from the extract.
A18: Everything in this workbook is synthetic (release data-v13). Published customs datasets record an irregularity on 1 to 8 lines in 100; in this lab the random draw finds 3 in 100.

Sheet Parameters
A1: Parameters · every threshold of the breakout in one place
A2: Every formula reads its threshold here. Change one, and every sheet follows. The weights and the dial are choices: say them out loud. Rows 21 to 24 say where the months and the VAT periods start, for the month and the period number you derive on S2 Four lists.
A4: parameter | B4: value | C4: note
A5: Weight of the name similarity | B5: 0.4 | C5: The deck's recipe; a choice, not a measurement.
A6: Weight of the address similarity | B6: 0.3 | C6: Idem.
A7: Weight of the director similarity | B7: 0.3 | C7: Idem.
A8: Dial: a link at or above | B8: 0.9 | C8: Set on the labelled sample (S1 Track B).
A9: Dial: a person reviews at or above | B9: 0.7 | C9: Below it: no link.
A10: VAT rate | B10: 0.1 | C10: The lab's rate.
A11: First period number of the last six returns | B11: 19 | C11: Periods 19 to 24 = 2026-04 to 2026-09.
A12: First period number of the last twelve returns | B12: 13 | C12: Periods 13 to 24 = 2025-10 to 2026-09.
A13: First customs month of the last twelve months | B13: 25 | C13: Months 25 to 36 = 2025-10 to 2026-09.
A14: Filing: at least this many of the last six returns | B14: 5 | C14: Question 2.
A15: Imports in its books: deducted ÷ paid at least | B15: 0.5 | C15: Question 3.
A16: Sold: sales ÷ imports at least | B16: 1 | C16: Question 4.
... A21: VAT period 1: its year | B21: 2024 | C21: Period number 1 = 2024-10, 24 = 2026-09: period number = (year − this) × 12 + month − the row below + 1.
A22: VAT period 1: its calendar month | B22: 10
A23: Customs month 1: its year | B23: 2023 | C23: Month 1 = October 2023, month 36 = September 2026: month = (year − this) × 12 + calendar month − the row below + 1.
A24: Customs month 1: its calendar month | B24: 10

Sheet S1 Match
A1: Sprint 1 · the 25 importers against the tax register: who is who
A2: Each row: the importer as customs holds it (columns A to F and T, rows copied from the Customs importers sheet for the 25 importer codes of the breakout), and the tax register's best candidate (column G, found by a search on name and address). The candidate and the similarities are computed for you (purple, from the Similarities sheet): how alike the two strings are once cleaned. I01 and I17 are worked in grey.
A3: Your choice: 4B_lab.xlsx (sheet Match A) already has every confidence, and 4B_compute_worked.xlsx every formula.
A5: Step | B5: What to do | H5: Your answer | I5: Check | J5: Hint 1 · the tool (the full formula is on the Hints sheet)
A6: 1 | B6: Column K: does the tax number on the declaration exist in the tax register, as typed? "matched", "not in the register" or "blank". Then: how many rows match exactly? | H6: =COUNTIF(K16:K40,"matched") | I6: =IF(H6="","",IF(ISNUMBER(H6),IF(ABS(H6-_check!$B$2)<=0.5,"✓ matches","✗ not yet: see the hint"),"✗ not yet: see the hint")) | J6: COUNTIF counts the number in the register's tax ID column; IF turns the count into a word.
A7: 2 | B7: Column P: the match confidence: name × 0.4 + address × 0.3 + director × 0.3, a missing field left out and the weights rescaled over the fields present. Then: I17's confidence. | H7: =P32 | I7: =IF(H7="","",IF(ISNUMBER(H7),IF(ABS(H7-_check!$B$3)<=0.0006,"✓ matches","✗ not yet: see the hint"),"✗ not yet: see the hint")) | J7: N() turns an empty cell into 0; ISNUMBER says which fields are present, so the division rescales the weights.
A8: 3 | B8: Column Q: the class at the dial: exact when the number matched; validated probable at or above the link line; review between the two lines (a person decides); no link below. Then: how many rows wait in the review band? | H8: =COUNTIF(Q16:Q40,"review") | I8: =IF(H8="","",IF(ISNUMBER(H8),IF(ABS(H8-_check!$B$4)<=0.5,"✓ matches","✗ not yet: see the hint"),"✗ not yet: see the hint")) | J8: IF inside IF, reading the two lines of the dial on the Parameters sheet.
A9: 4 | B9: Column R: the tax number on the tax side: the declared number when exact; the register's candidate when validated probable; nothing otherwise. Then: how many of the 25 rows have a tax number on the tax side? | H9: =SUMPRODUCT(--(R16:R40<>"")) | I9: =IF(H9="","",IF(ISNUMBER(H9),IF(ABS(H9-_check!$B$5)<=0.5,"✓ matches","✗ not yet: see the hint"),"✗ not yet: see the hint")) | J9: IF on the class. Then count the cells of column R that are not empty.
A10: 5 | B10: Your class (column S): the class at the dial, unless your group decides a review-band pair after reading both records. Lock class and confidence for the 25 on the site. | J10: A wrong link costs more than a missed one: a letter to the wrong trader. Count the four classes; do not quote one match rate.
A11: 6 | B11: Before step 5, columns H to J: the candidate's record from the Tax register (legal name, address, director), so that a person can read both records; column O: 1 when the candidate's phone is the customs phone. Then: how many of the 25 pairs share the phone? | H11: =SUM(O16:O40) | I11: =IF(H11="","",IF(ISNUMBER(H11),IF(ABS(H11-_check!$B$164)<=0.5,"✓ matches","✗ not yet: see the hint"),"✗ not yet: see the hint")) | J11: VLOOKUP finds the candidate's tax number (column G) in the first column of the Tax register and returns its 2nd column (legal name), 4th (address), 7th (director) or 6th (phone); IFERROR leaves a missing one empty.
A15: ref | B15: importer (customs) | C15: tax number on the declaration | D15: address (customs) | E15: phone (customs) | F15: director (customs) | G15: best candidate: tax ID · computed for you | H15: best candidate: legal name (you) | I15: best candidate: address (you) | J15: best candidate: director (you) | K15: tax number as typed | L15: name similarity · computed for you | M15: address similarity · computed for you | N15: director similarity · computed for you | O15: phone match (1/0) · you | P15: confidence | Q15: class at the dial | R15: tax number on the tax side | S15: your class | T15: importer code
A16: I01 | B16: Ocean Electronics Co., Ltd | C16: T103629 | D16: 222 Mill Road | E16: 0817809823 | F16: Somchai Rahman | G16: T103629 | H16: =IFERROR(VLOOKUP($G16,'Tax register'!$A$5:$K$1803,2,FALSE),"") | I16: =IFERROR(VLOOKUP($G16,'Tax register'!$A$5:$K$1803,4,FALSE),"") | J16: =IFERROR(VLOOKUP($G16,'Tax register'!$A$5:$K$1803,7,FALSE),"") | K16: =IF(C16="","blank",IF(COUNTIF('Tax register'!$A$5:$A$1803,C16)>0,"matched","not in the register")) | L16: 1 | M16: 1 | N16: 1 | O16: =IF(IFERROR(VLOOKUP($G16,'Tax register'!$A$5:$K$1803,6,FALSE),"")=E16,1,0) | P16: =IF(COUNT(L16:N16)=0,0,(Parameters!$B$5*N(L16)+Parameters!$B$6*N(M16)+Parameters!$B$7*N(N16))/(Parameters!$B$5*ISNUMBER(L16)+Parameters!$B$6*ISNUMBER(M16)+Parameters!$B$7*ISNUMBER(N16))) | Q16: =IF(K16="matched","exact",IF(P16>=Parameters!$B$8,"validated probable",IF(P16>=Parameters!$B$9,"review","no link"))) | R16: =IF(S16="exact",C16,IF(S16="validated probable",G16,"")) | S16: =Q16 | T16: IMP00519
A17: I02 | B17: Phoenix Glow Limited | C17: T105264 | D17: 248 Industrial Estate | E17: 0496195011 | F17: Tomas Tanaka | G17: T105264 | H17: =IFERROR(VLOOKUP($G17,'Tax register'!$A$5:$K$1803,2,FALSE),"") | I17: =IFERROR(VLOOKUP($G17,'Tax register'!$A$5:$K$1803,4,FALSE),"") | J17: =IFERROR(VLOOKUP($G17,'Tax register'!$A$5:$K$1803,7,FALSE),"") | K17: =IF(C17="","blank",IF(COUNTIF('Tax register'!$A$5:$A$1803,C17)>0,"matched","not in the register")) | L17: 1 | M17: 1 | N17: 1 | O17: =IF(IFERROR(VLOOKUP($G17,'Tax register'!$A$5:$K$1803,6,FALSE),"")=E17,1,0) | P17: =IF(COUNT(L17:N17)=0,0,(Parameters!$B$5*N(L17)+Parameters!$B$6*N(M17)+Parameters!$B$7*N(N17))/(Parameters!$B$5*ISNUMBER(L17)+Parameters!$B$6*ISNUMBER(M17)+Parameters!$B$7*ISNUMBER(N17))) | Q17: =IF(K17="matched","exact",IF(P17>=Parameters!$B$8,"validated probable",IF(P17>=Parameters!$B$9,"review","no link"))) | R17: =IF(S17="exact",C17,IF(S17="validated probable",G17,"")) | S17: =Q17 | T17: IMP00753
A18: I03 | B18: Delta Fruits Holdings Ltd | C18: T106240 | D18: 340 Industrial Estate | E18: 0459640429 | F18: Joseph Rahman | G18: T106240 | H18: =IFERROR(VLOOKUP($G18,'Tax register'!$A$5:$K$1803,2,FALSE),"") | I18: =IFERROR(VLOOKUP($G18,'Tax register'!$A$5:$K$1803,4,FALSE),"") | J18: =IFERROR(VLOOKUP($G18,'Tax register'!$A$5:$K$1803,7,FALSE),"") | K18: =IF(C18="","blank",IF(COUNTIF('Tax register'!$A$5:$A$1803,C18)>0,"matched","not in the register")) | L18: 1 | M18: 1 | N18: 1 | O18: =IF(IFERROR(VLOOKUP($G18,'Tax register'!$A$5:$K$1803,6,FALSE),"")=E18,1,0) | P18: =IF(COUNT(L18:N18)=0,0,(Parameters!$B$5*N(L18)+Parameters!$B$6*N(M18)+Parameters!$B$7*N(N18))/(Parameters!$B$5*ISNUMBER(L18)+Parameters!$B$6*ISNUMBER(M18)+Parameters!$B$7*ISNUMBER(N18))) | Q18: =IF(K18="matched","exact",IF(P18>=Parameters!$B$8,"validated probable",IF(P18>=Parameters!$B$9,"review","no link"))) | R18: =IF(S18="exact",C18,IF(S18="validated probable",G18,"")) | S18: =Q18 | T18: IMP00892
A19: I04 | B19: Great Vellmoor Steel Enterprises | C19: T102376 | D19: 43 Riverside | E19: 0913214249 | F19: Elena Haddad | G19: T102376 | H19: =IFERROR(VLOOKUP($G19,'Tax register'!$A$5:$K$1803,2,FALSE),"") | I19: =IFERROR(VLOOKUP($G19,'Tax register'!$A$5:$K$1803,4,FALSE),"") | J19: =IFERROR(VLOOKUP($G19,'Tax register'!$A$5:$K$1803,7,FALSE),"") | K19: =IF(C19="","blank",IF(COUNTIF('Tax register'!$A$5:$A$1803,C19)>0,"matched","not in the register")) | L19: 1 | M19: 1 | N19: 1 | O19: =IF(IFERROR(VLOOKUP($G19,'Tax register'!$A$5:$K$1803,6,FALSE),"")=E19,1,0) | P19: =IF(COUNT(L19:N19)=0,0,(Parameters!$B$5*N(L19)+Parameters!$B$6*N(M19)+Parameters!$B$7*N(N19))/(Parameters!$B$5*ISNUMBER(L19)+Parameters!$B$6*ISNUMBER(M19)+Parameters!$B$7*ISNUMBER(N19))) | Q19: =IF(K19="matched","exact",IF(P19>=Parameters!$B$8,"validated probable",IF(P19>=Parameters!$B$9,"review","no link"))) | R19: =IF(S19="exact",C19,IF(S19="validated probable",G19,"")) | S19: =Q19 | T19: IMP00340
A20: I05 | B20: Carrick Electronics Group Ltd | C20: T106987 | D20: 375 Industrial Estate | E20: 0719832200 | F20: Farid Okafor | G20: T106987 | H20: =IFERROR(VLOOKUP($G20,'Tax register'!$A$5:$K$1803,2,FALSE),"") | I20: =IFERROR(VLOOKUP($G20,'Tax register'!$A$5:$K$1803,4,FALSE),"") | J20: =IFERROR(VLOOKUP($G20,'Tax register'!$A$5:$K$1803,7,FALSE),"") | K20: =IF(C20="","blank",IF(COUNTIF('Tax register'!$A$5:$A$1803,C20)>0,"matched","not in the register")) | L20: 1 | M20: 1 | N20: 1 | O20: =IF(IFERROR(VLOOKUP($G20,'Tax register'!$A$5:$K$1803,6,FALSE),"")=E20,1,0) | P20: =IF(COUNT(L20:N20)=0,0,(Parameters!$B$5*N(L20)+Parameters!$B$6*N(M20)+Parameters!$B$7*N(N20))/(Parameters!$B$5*ISNUMBER(L20)+Parameters!$B$6*ISNUMBER(M20)+Parameters!$B$7*ISNUMBER(N20))) | Q20: =IF(K20="matched","exact",IF(P20>=Parameters!$B$8,"validated probable",IF(P20>=Parameters!$B$9,"review","no link"))) | R20: =IF(S20="exact",C20,IF(S20="validated probable",G20,"")) | S20: =Q20 | T20: IMP00999
A21: I06 | B21: Carrick Agro Enterprises | C21: T107258 | D21: 18 Market Street | E21: 0545102251 | F21: Kenji Haddad | G21: T107258 | H21: =IFERROR(VLOOKUP($G21,'Tax register'!$A$5:$K$1803,2,FALSE),"") | I21: =IFERROR(VLOOKUP($G21,'Tax register'!$A$5:$K$1803,4,FALSE),"") | J21: =IFERROR(VLOOKUP($G21,'Tax register'!$A$5:$K$1803,7,FALSE),"") | K21: =IF(C21="","blank",IF(COUNTIF('Tax register'!$A$5:$A$1803,C21)>0,"matched","not in the register")) | L21: 1 | M21: 1 | N21: 1 | O21: =IF(IFERROR(VLOOKUP($G21,'Tax register'!$A$5:$K$1803,6,FALSE),"")=E21,1,0) | P21: =IF(COUNT(L21:N21)=0,0,(Parameters!$B$5*N(L21)+Parameters!$B$6*N(M21)+Parameters!$B$7*N(N21))/(Parameters!$B$5*ISNUMBER(L21)+Parameters!$B$6*ISNUMBER(M21)+Parameters!$B$7*ISNUMBER(N21))) | Q21: =IF(K21="matched","exact",IF(P21>=Parameters!$B$8,"validated probable",IF(P21>=Parameters!$B$9,"review","no link"))) | R21: =IF(S21="exact",C21,IF(S21="validated probable",G21,"")) | S21: =Q21 | T21: IMP01037
A22: I07 | B22: Cobalt Mobile & Sons | C22: T102141 | D22: 314 Industrial Estate | E22: 0965281846 | F22: Elena Haddad | G22: T102141 | H22: =IFERROR(VLOOKUP($G22,'Tax register'!$A$5:$K$1803,2,FALSE),"") | I22: =IFERROR(VLOOKUP($G22,'Tax register'!$A$5:$K$1803,4,FALSE),"") | J22: =IFERROR(VLOOKUP($G22,'Tax register'!$A$5:$K$1803,7,FALSE),"") | K22: =IF(C22="","blank",IF(COUNTIF('Tax register'!$A$5:$A$1803,C22)>0,"matched","not in the register")) | L22: 1 | M22: 1 | N22: 1 | O22: =IF(IFERROR(VLOOKUP($G22,'Tax register'!$A$5:$K$1803,6,FALSE),"")=E22,1,0) | P22: =IF(COUNT(L22:N22)=0,0,(Parameters!$B$5*N(L22)+Parameters!$B$6*N(M22)+Parameters!$B$7*N(N22))/(Parameters!$B$5*ISNUMBER(L22)+Parameters!$B$6*ISNUMBER(M22)+Parameters!$B$7*ISNUMBER(N22))) | Q22: =IF(K22="matched","exact",IF(P22>=Parameters!$B$8,"validated probable",IF(P22>=Parameters!$B$9,"review","no link"))) | R22: =IF(S22="exact",C22,IF(S22="validated probable",G22,"")) | S22: =Q22 | T22: IMP00306
A23: I08 | B23: Central Imports International Ltd | D23: 350 Garden Lane | E23: 0471338762 | F23: Kenji Haddad | G23: T102182 | H23: =IFERROR(VLOOKUP($G23,'Tax register'!$A$5:$K$1803,2,FALSE),"") | I23: =IFERROR(VLOOKUP($G23,'Tax register'!$A$5:$K$1803,4,FALSE),"") | J23: =IFERROR(VLOOKUP($G23,'Tax register'!$A$5:$K$1803,7,FALSE),"") | K23: =IF(C23="","blank",IF(COUNTIF('Tax register'!$A$5:$A$1803,C23)>0,"matched","not in the register")) | L23: 1 | M23: 0.615 | N23: 0.345 | O23: =IF(IFERROR(VLOOKUP($G23,'Tax register'!$A$5:$K$1803,6,FALSE),"")=E23,1,0) | P23: =IF(COUNT(L23:N23)=0,0,(Parameters!$B$5*N(L23)+Parameters!$B$6*N(M23)+Parameters!$B$7*N(N23))/(Parameters!$B$5*ISNUMBER(L23)+Parameters!$B$6*ISNUMBER(M23)+Parameters!$B$7*ISNUMBER(N23))) | Q23: =IF(K23="matched","exact",IF(P23>=Parameters!$B$8,"validated probable",IF(P23>=Parameters!$B$9,"review","no link"))) | R23: =IF(S23="exact",C23,IF(S23="validated probable",G23,"")) | S23: =Q23 | T23: IMP00147
A24: I09 | B24: Phoenix Imports Partners Ltd | D24: 171 Garden Lane | E24: 0887356246 | F24: Nadia Chen | G24: T514418 | H24: =IFERROR(VLOOKUP($G24,'Tax register'!$A$5:$K$1803,2,FALSE),"") | I24: =IFERROR(VLOOKUP($G24,'Tax register'!$A$5:$K$1803,4,FALSE),"") | J24: =IFERROR(VLOOKUP($G24,'Tax register'!$A$5:$K$1803,7,FALSE),"") | K24: =IF(C24="","blank",IF(COUNTIF('Tax register'!$A$5:$A$1803,C24)>0,"matched","not in the register")) | L24: 1 | M24: 0.417 | N24: 0.4 | O24: =IF(IFERROR(VLOOKUP($G24,'Tax register'!$A$5:$K$1803,6,FALSE),"")=E24,1,0) | P24: =IF(COUNT(L24:N24)=0,0,(Parameters!$B$5*N(L24)+Parameters!$B$6*N(M24)+Parameters!$B$7*N(N24))/(Parameters!$B$5*ISNUMBER(L24)+Parameters!$B$6*ISNUMBER(M24)+Parameters!$B$7*ISNUMBER(N24))) | Q24: =IF(K24="matched","exact",IF(P24>=Parameters!$B$8,"validated probable",IF(P24>=Parameters!$B$9,"review","no link"))) | R24: =IF(S24="exact",C24,IF(S24="validated probable",G24,"")) | S24: =Q24 | T24: IMP00721
A25: I10 | B25: Global Electronics International Ltd | C25: T103130 | D25: 296 Temple Street | E25: 0941933516 | F25: Amina Al-Sayed | G25: T103130 | H25: =IFERROR(VLOOKUP($G25,'Tax register'!$A$5:$K$1803,2,FALSE),"") | I25: =IFERROR(VLOOKUP($G25,'Tax register'!$A$5:$K$1803,4,FALSE),"") | J25: =IFERROR(VLOOKUP($G25,'Tax register'!$A$5:$K$1803,7,FALSE),"") | K25: =IF(C25="","blank",IF(COUNTIF('Tax register'!$A$5:$A$1803,C25)>0,"matched","not in the register")) | L25: 1 | N25: 1 | O25: =IF(IFERROR(VLOOKUP($G25,'Tax register'!$A$5:$K$1803,6,FALSE),"")=E25,1,0) | P25: =IF(COUNT(L25:N25)=0,0,(Parameters!$B$5*N(L25)+Parameters!$B$6*N(M25)+Parameters!$B$7*N(N25))/(Parameters!$B$5*ISNUMBER(L25)+Parameters!$B$6*ISNUMBER(M25)+Parameters!$B$7*ISNUMBER(N25))) | Q25: =IF(K25="matched","exact",IF(P25>=Parameters!$B$8,"validated probable",IF(P25>=Parameters!$B$9,"review","no link"))) | R25: =IF(S25="exact",C25,IF(S25="validated probable",G25,"")) | S25: =Q25 | T25: IMP00448
A26: I11 | B26: Central Foods Limited | C26: T100033 | D26: 24 Harbour Road | E26: 0401520138 | F26: Farid Ibrahim | G26: T100033 | H26: =IFERROR(VLOOKUP($G26,'Tax register'!$A$5:$K$1803,2,FALSE),"") | I26: =IFERROR(VLOOKUP($G26,'Tax register'!$A$5:$K$1803,4,FALSE),"") | J26: =IFERROR(VLOOKUP($G26,'Tax register'!$A$5:$K$1803,7,FALSE),"") | K26: =IF(C26="","blank",IF(COUNTIF('Tax register'!$A$5:$A$1803,C26)>0,"matched","not in the register")) | L26: 1 | M26: 1 | N26: 1 | O26: =IF(IFERROR(VLOOKUP($G26,'Tax register'!$A$5:$K$1803,6,FALSE),"")=E26,1,0) | P26: =IF(COUNT(L26:N26)=0,0,(Parameters!$B$5*N(L26)+Parameters!$B$6*N(M26)+Parameters!$B$7*N(N26))/(Parameters!$B$5*ISNUMBER(L26)+Parameters!$B$6*ISNUMBER(M26)+Parameters!$B$7*ISNUMBER(N26))) | Q26: =IF(K26="matched","exact",IF(P26>=Parameters!$B$8,"validated probable",IF(P26>=Parameters!$B$9,"review","no link"))) | R26: =IF(S26="exact",C26,IF(S26="validated probable",G26,"")) | S26: =Q26 | T26: IMP00005
A27: I12 | B27: Ocean Medical Co., Ltd | D27: 362 Temple Street | E27: 0482336020 | F27: Hassan Tanaka | G27: T109212 | H27: =IFERROR(VLOOKUP($G27,'Tax register'!$A$5:$K$1803,2,FALSE),"") | I27: =IFERROR(VLOOKUP($G27,'Tax register'!$A$5:$K$1803,4,FALSE),"") | J27: =IFERROR(VLOOKUP($G27,'Tax register'!$A$5:$K$1803,7,FALSE),"") | K27: =IF(C27="","blank",IF(COUNTIF('Tax register'!$A$5:$A$1803,C27)>0,"matched","not in the register")) | L27: 1 | M27: 0.846 | N27: 0.32 | O27: =IF(IFERROR(VLOOKUP($G27,'Tax register'!$A$5:$K$1803,6,FALSE),"")=E27,1,0) | P27: =IF(COUNT(L27:N27)=0,0,(Parameters!$B$5*N(L27)+Parameters!$B$6*N(M27)+Parameters!$B$7*N(N27))/(Parameters!$B$5*ISNUMBER(L27)+Parameters!$B$6*ISNUMBER(M27)+Parameters!$B$7*ISNUMBER(N27))) | Q27: =IF(K27="matched","exact",IF(P27>=Parameters!$B$8,"validated probable",IF(P27>=Parameters!$B$9,"review","no link"))) | R27: =IF(S27="exact",C27,IF(S27="validated probable",G27,"")) | S27: =Q27 | T27: IMP00156
A28: I13 | B28: Central Enterprises Co. | D28: 191 Garden Lane | E28: 0946646378 | F28: Hassan Kowalski | G28: T110150 | H28: =IFERROR(VLOOKUP($G28,'Tax register'!$A$5:$K$1803,2,FALSE),"") | I28: =IFERROR(VLOOKUP($G28,'Tax register'!$A$5:$K$1803,4,FALSE),"") | J28: =IFERROR(VLOOKUP($G28,'Tax register'!$A$5:$K$1803,7,FALSE),"") | K28: =IF(C28="","blank",IF(COUNTIF('Tax register'!$A$5:$A$1803,C28)>0,"matched","not in the register")) | L28: 1 | M28: 0.846 | N28: 0.4 | O28: =IF(IFERROR(VLOOKUP($G28,'Tax register'!$A$5:$K$1803,6,FALSE),"")=E28,1,0) | P28: =IF(COUNT(L28:N28)=0,0,(Parameters!$B$5*N(L28)+Parameters!$B$6*N(M28)+Parameters!$B$7*N(N28))/(Parameters!$B$5*ISNUMBER(L28)+Parameters!$B$6*ISNUMBER(M28)+Parameters!$B$7*ISNUMBER(N28))) | Q28: =IF(K28="matched","exact",IF(P28>=Parameters!$B$8,"validated probable",IF(P28>=Parameters!$B$9,"review","no link"))) | R28: =IF(S28="exact",C28,IF(S28="validated probable",G28,"")) | S28: =Q28 | T28: IMP00950
A29: I14 | B29: Royal Agro Co., Ltd | C29: T108692 | D29: 191 Bazaar Lane | E29: 0382439044 | F29: Somchai Silva | G29: T108692 | H29: =IFERROR(VLOOKUP($G29,'Tax register'!$A$5:$K$1803,2,FALSE),"") | I29: =IFERROR(VLOOKUP($G29,'Tax register'!$A$5:$K$1803,4,FALSE),"") | J29: =IFERROR(VLOOKUP($G29,'Tax register'!$A$5:$K$1803,7,FALSE),"") | K29: =IF(C29="","blank",IF(COUNTIF('Tax register'!$A$5:$A$1803,C29)>0,"matched","not in the register")) | L29: 1 | M29: 1 | N29: 1 | O29: =IF(IFERROR(VLOOKUP($G29,'Tax register'!$A$5:$K$1803,6,FALSE),"")=E29,1,0) | P29: =IF(COUNT(L29:N29)=0,0,(Parameters!$B$5*N(L29)+Parameters!$B$6*N(M29)+Parameters!$B$7*N(N29))/(Parameters!$B$5*ISNUMBER(L29)+Parameters!$B$6*ISNUMBER(M29)+Parameters!$B$7*ISNUMBER(N29))) | Q29: =IF(K29="matched","exact",IF(P29>=Parameters!$B$8,"validated probable",IF(P29>=Parameters!$B$9,"review","no link"))) | R29: =IF(S29="exact",C29,IF(S29="validated probable",G29,"")) | S29: =Q29 | T29: IMP01242
A30: I15 | B30: Silk Road Steel Co. | C30: T100070 | D30: 346 Market Street | E30: 0519965779 | F30: Farid Haddad | G30: T100070 | H30: =IFERROR(VLOOKUP($G30,'Tax register'!$A$5:$K$1803,2,FALSE),"") | I30: =IFERROR(VLOOKUP($G30,'Tax register'!$A$5:$K$1803,4,FALSE),"") | J30: =IFERROR(VLOOKUP($G30,'Tax register'!$A$5:$K$1803,7,FALSE),"") | K30: =IF(C30="","blank",IF(COUNTIF('Tax register'!$A$5:$A$1803,C30)>0,"matched","not in the register")) | L30: 1 | M30: 1 | N30: 1 | O30: =IF(IFERROR(VLOOKUP($G30,'Tax register'!$A$5:$K$1803,6,FALSE),"")=E30,1,0) | P30: =IF(COUNT(L30:N30)=0,0,(Parameters!$B$5*N(L30)+Parameters!$B$6*N(M30)+Parameters!$B$7*N(N30))/(Parameters!$B$5*ISNUMBER(L30)+Parameters!$B$6*ISNUMBER(M30)+Parameters!$B$7*ISNUMBER(N30))) | Q30: =IF(K30="matched","exact",IF(P30>=Parameters!$B$8,"validated probable",IF(P30>=Parameters!$B$9,"review","no link"))) | R30: =IF(S30="exact",C30,IF(S30="validated probable",G30,"")) | S30: =Q30 | T30: IMP00011
A31: I16 | B31: Carrick Trading & Sons | C31: T107617 | D31: 172 Airport Road | E31: 0803847861 | F31: Ingrid Sato | G31: T107617 | H31: =IFERROR(VLOOKUP($G31,'Tax register'!$A$5:$K$1803,2,FALSE),"") | I31: =IFERROR(VLOOKUP($G31,'Tax register'!$A$5:$K$1803,4,FALSE),"") | J31: =IFERROR(VLOOKUP($G31,'Tax register'!$A$5:$K$1803,7,FALSE),"") | K31: =IF(C31="","blank",IF(COUNTIF('Tax register'!$A$5:$A$1803,C31)>0,"matched","not in the register")) | L31: 1 | M31: 1 | N31: 1 | O31: =IF(IFERROR(VLOOKUP($G31,'Tax register'!$A$5:$K$1803,6,FALSE),"")=E31,1,0) | P31: =IF(COUNT(L31:N31)=0,0,(Parameters!$B$5*N(L31)+Parameters!$B$6*N(M31)+Parameters!$B$7*N(N31))/(Parameters!$B$5*ISNUMBER(L31)+Parameters!$B$6*ISNUMBER(M31)+Parameters!$B$7*ISNUMBER(N31))) | Q31: =IF(K31="matched","exact",IF(P31>=Parameters!$B$8,"validated probable",IF(P31>=Parameters!$B$9,"review","no link"))) | R31: =IF(S31="exact",C31,IF(S31="validated probable",G31,"")) | S31: =Q31 | T31: IMP01089
A32: I17 | B32: Ocean Industries Holdings Ltd | D32: 323 Station Road | E32: 0924121092 | F32: Joseph Tanaka | G32: T106372 | H32: =IFERROR(VLOOKUP($G32,'Tax register'!$A$5:$K$1803,2,FALSE),"") | I32: =IFERROR(VLOOKUP($G32,'Tax register'!$A$5:$K$1803,4,FALSE),"") | J32: =IFERROR(VLOOKUP($G32,'Tax register'!$A$5:$K$1803,7,FALSE),"") | K32: =IF(C32="","blank",IF(COUNTIF('Tax register'!$A$5:$A$1803,C32)>0,"matched","not in the register")) | L32: 1 | M32: 0.857 | N32: 0.4 | O32: =IF(IFERROR(VLOOKUP($G32,'Tax register'!$A$5:$K$1803,6,FALSE),"")=E32,1,0) | P32: =IF(COUNT(L32:N32)=0,0,(Parameters!$B$5*N(L32)+Parameters!$B$6*N(M32)+Parameters!$B$7*N(N32))/(Parameters!$B$5*ISNUMBER(L32)+Parameters!$B$6*ISNUMBER(M32)+Parameters!$B$7*ISNUMBER(N32))) | Q32: =IF(K32="matched","exact",IF(P32>=Parameters!$B$8,"validated probable",IF(P32>=Parameters!$B$9,"review","no link"))) | R32: =IF(S32="exact",C32,IF(S32="validated probable",G32,"")) | S32: =Q32 | T32: IMP01481
A33: I18 | B33: Arden Living Co. | C33: T107992 | D33: 144 Riverside | E33: 0894167333 | F33: Samuel Kowalski | G33: T107992 | H33: =IFERROR(VLOOKUP($G33,'Tax register'!$A$5:$K$1803,2,FALSE),"") | I33: =IFERROR(VLOOKUP($G33,'Tax register'!$A$5:$K$1803,4,FALSE),"") | J33: =IFERROR(VLOOKUP($G33,'Tax register'!$A$5:$K$1803,7,FALSE),"") | K33: =IF(C33="","blank",IF(COUNTIF('Tax register'!$A$5:$A$1803,C33)>0,"matched","not in the register")) | L33: 1 | M33: 1 | N33: 1 | O33: =IF(IFERROR(VLOOKUP($G33,'Tax register'!$A$5:$K$1803,6,FALSE),"")=E33,1,0) | P33: =IF(COUNT(L33:N33)=0,0,(Parameters!$B$5*N(L33)+Parameters!$B$6*N(M33)+Parameters!$B$7*N(N33))/(Parameters!$B$5*ISNUMBER(L33)+Parameters!$B$6*ISNUMBER(M33)+Parameters!$B$7*ISNUMBER(N33))) | Q33: =IF(K33="matched","exact",IF(P33>=Parameters!$B$8,"validated probable",IF(P33>=Parameters!$B$9,"review","no link"))) | R33: =IF(S33="exact",C33,IF(S33="validated probable",G33,"")) | S33: =Q33 | T33: IMP01142
A34: I19 | B34: Pacific Living Co. | C34: T109167 | D34: 329 Riverside | E34: 0346234502 | F34: Aisha Reyes | G34: T109167 | H34: =IFERROR(VLOOKUP($G34,'Tax register'!$A$5:$K$1803,2,FALSE),"") | I34: =IFERROR(VLOOKUP($G34,'Tax register'!$A$5:$K$1803,4,FALSE),"") | J34: =IFERROR(VLOOKUP($G34,'Tax register'!$A$5:$K$1803,7,FALSE),"") | K34: =IF(C34="","blank",IF(COUNTIF('Tax register'!$A$5:$A$1803,C34)>0,"matched","not in the register")) | L34: 1 | M34: 1 | N34: 1 | O34: =IF(IFERROR(VLOOKUP($G34,'Tax register'!$A$5:$K$1803,6,FALSE),"")=E34,1,0) | P34: =IF(COUNT(L34:N34)=0,0,(Parameters!$B$5*N(L34)+Parameters!$B$6*N(M34)+Parameters!$B$7*N(N34))/(Parameters!$B$5*ISNUMBER(L34)+Parameters!$B$6*ISNUMBER(M34)+Parameters!$B$7*ISNUMBER(N34))) | Q34: =IF(K34="matched","exact",IF(P34>=Parameters!$B$8,"validated probable",IF(P34>=Parameters!$B$9,"review","no link"))) | R34: =IF(S34="exact",C34,IF(S34="validated probable",G34,"")) | S34: =Q34 | T34: IMP01310
A35: I20 | B35: Ocean Trading International Ltd | C35: T103425 | D35: 115 Harbour Road | E35: 0731410108 | F35: Nadia Al-Sayed | G35: T103425 | H35: =IFERROR(VLOOKUP($G35,'Tax register'!$A$5:$K$1803,2,FALSE),"") | I35: =IFERROR(VLOOKUP($G35,'Tax register'!$A$5:$K$1803,4,FALSE),"") | J35: =IFERROR(VLOOKUP($G35,'Tax register'!$A$5:$K$1803,7,FALSE),"") | K35: =IF(C35="","blank",IF(COUNTIF('Tax register'!$A$5:$A$1803,C35)>0,"matched","not in the register")) | L35: 1 | M35: 1 | N35: 1 | O35: =IF(IFERROR(VLOOKUP($G35,'Tax register'!$A$5:$K$1803,6,FALSE),"")=E35,1,0) | P35: =IF(COUNT(L35:N35)=0,0,(Parameters!$B$5*N(L35)+Parameters!$B$6*N(M35)+Parameters!$B$7*N(N35))/(Parameters!$B$5*ISNUMBER(L35)+Parameters!$B$6*ISNUMBER(M35)+Parameters!$B$7*ISNUMBER(N35))) | Q35: =IF(K35="matched","exact",IF(P35>=Parameters!$B$8,"validated probable",IF(P35>=Parameters!$B$9,"review","no link"))) | R35: =IF(S35="exact",C35,IF(S35="validated probable",G35,"")) | S35: =Q35 | T35: IMP00490
A36: I21 | B36: Metro Motors Co., Ltd | C36: T100440 | D36: 215 Bazaar Lane | E36: 0929915234 | F36: Ingrid Al-Sayed | G36: T100440 | H36: =IFERROR(VLOOKUP($G36,'Tax register'!$A$5:$K$1803,2,FALSE),"") | I36: =IFERROR(VLOOKUP($G36,'Tax register'!$A$5:$K$1803,4,FALSE),"") | J36: =IFERROR(VLOOKUP($G36,'Tax register'!$A$5:$K$1803,7,FALSE),"") | K36: =IF(C36="","blank",IF(COUNTIF('Tax register'!$A$5:$A$1803,C36)>0,"matched","not in the register")) | L36: 1 | M36: 1 | N36: 1 | O36: =IF(IFERROR(VLOOKUP($G36,'Tax register'!$A$5:$K$1803,6,FALSE),"")=E36,1,0) | P36: =IF(COUNT(L36:N36)=0,0,(Parameters!$B$5*N(L36)+Parameters!$B$6*N(M36)+Parameters!$B$7*N(N36))/(Parameters!$B$5*ISNUMBER(L36)+Parameters!$B$6*ISNUMBER(M36)+Parameters!$B$7*ISNUMBER(N36))) | Q36: =IF(K36="matched","exact",IF(P36>=Parameters!$B$8,"validated probable",IF(P36>=Parameters!$B$9,"review","no link"))) | R36: =IF(S36="exact",C36,IF(S36="validated probable",G36,"")) | S36: =Q36 | T36: IMP00063
A37: I22 | B37: Metro Steel Partners Ltd | C37: T106477 | D37: 358 Market Street | E37: 0402667378 | F37: Amina Bauer | G37: T106477 | H37: =IFERROR(VLOOKUP($G37,'Tax register'!$A$5:$K$1803,2,FALSE),"") | I37: =IFERROR(VLOOKUP($G37,'Tax register'!$A$5:$K$1803,4,FALSE),"") | J37: =IFERROR(VLOOKUP($G37,'Tax register'!$A$5:$K$1803,7,FALSE),"") | K37: =IF(C37="","blank",IF(COUNTIF('Tax register'!$A$5:$A$1803,C37)>0,"matched","not in the register")) | L37: 1 | M37: 1 | N37: 1 | O37: =IF(IFERROR(VLOOKUP($G37,'Tax register'!$A$5:$K$1803,6,FALSE),"")=E37,1,0) | P37: =IF(COUNT(L37:N37)=0,0,(Parameters!$B$5*N(L37)+Parameters!$B$6*N(M37)+Parameters!$B$7*N(N37))/(Parameters!$B$5*ISNUMBER(L37)+Parameters!$B$6*ISNUMBER(M37)+Parameters!$B$7*ISNUMBER(N37))) | Q37: =IF(K37="matched","exact",IF(P37>=Parameters!$B$8,"validated probable",IF(P37>=Parameters!$B$9,"review","no link"))) | R37: =IF(S37="exact",C37,IF(S37="validated probable",G37,"")) | S37: =Q37 | T37: IMP00926
A38: I23 | B38: Aldergate Agro Holdings Ltd | C38: T104498 | D38: 340 Garden Lane | E38: 0612702458 | F38: Daniel Osei | G38: T104498 | H38: =IFERROR(VLOOKUP($G38,'Tax register'!$A$5:$K$1803,2,FALSE),"") | I38: =IFERROR(VLOOKUP($G38,'Tax register'!$A$5:$K$1803,4,FALSE),"") | J38: =IFERROR(VLOOKUP($G38,'Tax register'!$A$5:$K$1803,7,FALSE),"") | K38: =IF(C38="","blank",IF(COUNTIF('Tax register'!$A$5:$A$1803,C38)>0,"matched","not in the register")) | L38: 1 | M38: 1 | N38: 1 | O38: =IF(IFERROR(VLOOKUP($G38,'Tax register'!$A$5:$K$1803,6,FALSE),"")=E38,1,0) | P38: =IF(COUNT(L38:N38)=0,0,(Parameters!$B$5*N(L38)+Parameters!$B$6*N(M38)+Parameters!$B$7*N(N38))/(Parameters!$B$5*ISNUMBER(L38)+Parameters!$B$6*ISNUMBER(M38)+Parameters!$B$7*ISNUMBER(N38))) | Q38: =IF(K38="matched","exact",IF(P38>=Parameters!$B$8,"validated probable",IF(P38>=Parameters!$B$9,"review","no link"))) | R38: =IF(S38="exact",C38,IF(S38="validated probable",G38,"")) | S38: =Q38 | T38: IMP00643
A39: I24 | B39: Pacific Enterprises Holdings Ltd | C39: T100466 | D39: 356 Station Road | E39: 0254736740 | F39: Farid Sato | G39: T100466 | H39: =IFERROR(VLOOKUP($G39,'Tax register'!$A$5:$K$1803,2,FALSE),"") | I39: =IFERROR(VLOOKUP($G39,'Tax register'!$A$5:$K$1803,4,FALSE),"") | J39: =IFERROR(VLOOKUP($G39,'Tax register'!$A$5:$K$1803,7,FALSE),"") | K39: =IF(C39="","blank",IF(COUNTIF('Tax register'!$A$5:$A$1803,C39)>0,"matched","not in the register")) | L39: 1 | M39: 1 | N39: 1 | O39: =IF(IFERROR(VLOOKUP($G39,'Tax register'!$A$5:$K$1803,6,FALSE),"")=E39,1,0) | P39: =IF(COUNT(L39:N39)=0,0,(Parameters!$B$5*N(L39)+Parameters!$B$6*N(M39)+Parameters!$B$7*N(N39))/(Parameters!$B$5*ISNUMBER(L39)+Parameters!$B$6*ISNUMBER(M39)+Parameters!$B$7*ISNUMBER(N39))) | Q39: =IF(K39="matched","exact",IF(P39>=Parameters!$B$8,"validated probable",IF(P39>=Parameters!$B$9,"review","no link"))) | R39: =IF(S39="exact",C39,IF(S39="validated probable",G39,"")) | S39: =Q39 | T39: IMP00067
A40: I25 | B40: Arden Fruits Enterprises | C40: T102011 | D40: 360 Harbour Road | E40: 0225352118 | F40: Mei Okafor | G40: T102015 | H40: =IFERROR(VLOOKUP($G40,'Tax register'!$A$5:$K$1803,2,FALSE),"") | I40: =IFERROR(VLOOKUP($G40,'Tax register'!$A$5:$K$1803,4,FALSE),"") | J40: =IFERROR(VLOOKUP($G40,'Tax register'!$A$5:$K$1803,7,FALSE),"") | K40: =IF(C40="","blank",IF(COUNTIF('Tax register'!$A$5:$A$1803,C40)>0,"matched","not in the register")) | L40: 1 | M40: 1 | N40: 1 | O40: =IF(IFERROR(VLOOKUP($G40,'Tax register'!$A$5:$K$1803,6,FALSE),"")=E40,1,0) | P40: =IF(COUNT(L40:N40)=0,0,(Parameters!$B$5*N(L40)+Parameters!$B$6*N(M40)+Parameters!$B$7*N(N40))/(Parameters!$B$5*ISNUMBER(L40)+Parameters!$B$6*ISNUMBER(M40)+Parameters!$B$7*ISNUMBER(N40))) | Q40: =IF(K40="matched","exact",IF(P40>=Parameters!$B$8,"validated probable",IF(P40>=Parameters!$B$9,"review","no link"))) | R40: =IF(S40="exact",C40,IF(S40="validated probable",G40,"")) | S40: =Q40 | T40: IMP00288
A42: The worked case, I17: no number on the declaration; the register's best candidate T106372 · name 1.00, address 0.857, director 0.40: 0.4 × 1.00 + 0.3 × 0.857 + 0.3 × 0.40 = 0.777, in the review band. A person reads both records before any letter.

Sheet S1 Track B
A1: Sprint 1 · Track B: a real register, and where to set the dial
A2: Left: the matching recipe's best candidate for each of 3,200 customs rows, with its score (computed for you). Middle: 300 pairs a clerk checked by hand (1 = the same trader, 0 = not). Rows by number only; no name is read aloud.
A3: Computed for you (purple): the score, by a script that compares cleaned names and addresses of a public register (match_scores.csv). The labels are a clerk's (trackB_labelled_sample.csv). Both are lab files: the extract does not carry them.
A5: customs row | B5: register row | C5: score | D5: band | F5: customs row | G5: register row | H5: label (1 = same) | I5: its score | K5: at the dial | L5: 0.5 | M5: 0.7 | N5: 0.9
A6: C00001 | B6: R01223 | C6: 1 | D6: exact | F6: C00018 | G6: R00507 | H6: 0 | I6: =VLOOKUP(F6,$A$6:$C$3205,3,FALSE) | K6: pairs at or above (all rows) | L6: =COUNTIF($C$6:$C$3205,">="&L$5) | M6: =COUNTIF($C$6:$C$3205,">="&M$5) | N6: =COUNTIF($C$6:$C$3205,">="&N$5)
A7: C00002 | B7: R00398 | C7: 1 | D7: exact | F7: C00020 | G7: R01739 | H7: 1 | I7: =VLOOKUP(F7,$A$6:$C$3205,3,FALSE) | K7: sample pairs at or above | L7: =COUNTIF($I$6:$I$305,">="&L$5) | M7: =COUNTIF($I$6:$I$305,">="&M$5) | N7: =COUNTIF($I$6:$I$305,">="&N$5)
A8: C00003 | B8: R02417 | C8: 1 | D8: exact | F8: C00028 | G8: R01517 | H8: 1 | I8: =VLOOKUP(F8,$A$6:$C$3205,3,FALSE) | K8: precision: true links ÷ sample pairs at or above | L8: =IFERROR(COUNTIFS($I$6:$I$305,">="&L$5,$H$6:$H$305,1)/L7,"") | M8: =IFERROR(COUNTIFS($I$6:$I$305,">="&M$5,$H$6:$H$305,1)/M7,"") | N8: =IFERROR(COUNTIFS($I$6:$I$305,">="&N$5,$H$6:$H$305,1)/N7,"")
A9: C00004 | B9: R01899 | C9: 1 | D9: exact | F9: C00031 | G9: R01600 | H9: 1 | I9: =VLOOKUP(F9,$A$6:$C$3205,3,FALSE) | K9: recall: true links at or above ÷ all true links | L9: =IFERROR(COUNTIFS($I$6:$I$305,">="&L$5,$H$6:$H$305,1)/COUNTIF($H$6:$H$305,1),"") | M9: =IFERROR(COUNTIFS($I$6:$I$305,">="&M$5,$H$6:$H$305,1)/COUNTIF($H$6:$H$305,1),"") | N9: =IFERROR(COUNTIFS($I$6:$I$305,">="&N$5,$H$6:$H$305,1)/COUNTIF($H$6:$H$305,1),"")
A10: C00005 | B10: R02666 | C10: 1 | D10: exact | F10: C00037 | G10: R02691 | H10: 1 | I10: =VLOOKUP(F10,$A$6:$C$3205,3,FALSE)
A11: C00006 | B11: R02060 | C11: 1 | D11: exact | F11: C00049 | G11: R00866 | H11: 1 | I11: =VLOOKUP(F11,$A$6:$C$3205,3,FALSE) | K11: checks (rows 6 to 9) | L11: =IF(COUNT($I$6:$I$305)<300,"",IF(L6="","",IF(ISNUMBER(L6),IF(ABS(L6-_check!$B$6)<=0.5,"✓","✗"),"✗"))) | M11: =IF(COUNT($I$6:$I$305)<300,"",IF(M6="","",IF(ISNUMBER(M6),IF(ABS(M6-_check!$B$7)<=0.5,"✓","✗"),"✗"))) | N11: =IF(COUNT($I$6:$I$305)<300,"",IF(N6="","",IF(ISNUMBER(N6),IF(ABS(N6-_check!$B$8)<=0.5,"✓","✗"),"✗")))
A12: C00007 | B12: R01228 | C12: 1 | D12: exact | F12: C00059 | G12: R00785 | H12: 1 | I12: =VLOOKUP(F12,$A$6:$C$3205,3,FALSE) | L12: =IF(COUNT($I$6:$I$305)<300,"",IF(L7="","",IF(ISNUMBER(L7),IF(ABS(L7-_check!$B$9)<=0.5,"✓","✗"),"✗"))) | M12: =IF(COUNT($I$6:$I$305)<300,"",IF(M7="","",IF(ISNUMBER(M7),IF(ABS(M7-_check!$B$10)<=0.5,"✓","✗"),"✗"))) | N12: =IF(COUNT($I$6:$I$305)<300,"",IF(N7="","",IF(ISNUMBER(N7),IF(ABS(N7-_check!$B$11)<=0.5,"✓","✗"),"✗")))
A13: C00008 | B13: R00709 | C13: 1 | D13: exact | F13: C00062 | G13: R02603 | H13: 1 | I13: =VLOOKUP(F13,$A$6:$C$3205,3,FALSE) | L13: =IF(COUNT($I$6:$I$305)<300,"",IF(L8="","",IF(ISNUMBER(L8),IF(ABS(L8-_check!$B$12)<=0.0006,"✓","✗"),"✗"))) | M13: =IF(COUNT($I$6:$I$305)<300,"",IF(M8="","",IF(ISNUMBER(M8),IF(ABS(M8-_check!$B$13)<=0.0006,"✓","✗"),"✗"))) | N13: =IF(COUNT($I$6:$I$305)<300,"",IF(N8="","",IF(ISNUMBER(N8),IF(ABS(N8-_check!$B$14)<=0.0006,"✓","✗"),"✗")))
A14: C00009 | B14: R01515 | C14: 0.4259 | D14: no match | F14: C00073 | G14: R00465 | H14: 1 | I14: =VLOOKUP(F14,$A$6:$C$3205,3,FALSE) | L14: =IF(COUNT($I$6:$I$305)<300,"",IF(L9="","",IF(ISNUMBER(L9),IF(ABS(L9-_check!$B$15)<=0.0006,"✓","✗"),"✗"))) | M14: =IF(COUNT($I$6:$I$305)<300,"",IF(M9="","",IF(ISNUMBER(M9),IF(ABS(M9-_check!$B$16)<=0.0006,"✓","✗"),"✗"))) | N14: =IF(COUNT($I$6:$I$305)<300,"",IF(N9="","",IF(ISNUMBER(N9),IF(ABS(N9-_check!$B$17)<=0.0006,"✓","✗"),"✗")))
A15: C00010 | B15: R00624 | C15: 0.6541 | D15: no match | F15: C00079 | G15: R01142 | H15: 1 | I15: =VLOOKUP(F15,$A$6:$C$3205,3,FALSE)
A16: C00011 | B16: R00446 | C16: 1 | D16: exact | F16: C00102 | G16: R01427 | H16: 1 | I16: =VLOOKUP(F16,$A$6:$C$3205,3,FALSE) | K16: Read the trade-off: a strict dial (0.9) is almost always right and misses most true links; a loose one (0.5) finds them and sends letters to the wrong trader. The sample is 300 pairs: a precision of 87% on 200 pairs can be anything from about 81% to 91%.
A17: C00012 | B17: R01431 | C17: 1 | D17: exact | F17: C00113 | G17: R00350 | H17: 1 | I17: =VLOOKUP(F17,$A$6:$C$3205,3,FALSE)
A18: C00013 | B18: R02150 | C18: 1 | D18: exact | F18: C00120 | G18: R01761 | H18: 1 | I18: =VLOOKUP(F18,$A$6:$C$3205,3,FALSE)
A19: C00014 | B19: R01423 | C19: 1 | D19: exact | F19: C00122 | G19: R01080 | H19: 1 | I19: =VLOOKUP(F19,$A$6:$C$3205,3,FALSE)
A20: C00015 | B20: R01242 | C20: 0.6541 | D20: no match | F20: C00140 | G20: R00812 | H20: 1 | I20: =VLOOKUP(F20,$A$6:$C$3205,3,FALSE)
A21: C00016 | B21: R02239 | C21: 1 | D21: exact | F21: C00142 | G21: R02154 | H21: 1 | I21: =VLOOKUP(F21,$A$6:$C$3205,3,FALSE)
A22: C00017 | B22: R01133 | C22: 0.6541 | D22: no match | F22: C00147 | G22: R02873 | H22: 1 | I22: =VLOOKUP(F22,$A$6:$C$3205,3,FALSE)
A23: C00018 | B23: R00507 | C23: 0.2202 | D23: no match | F23: C00148 | G23: R02192 | H23: 1 | I23: =VLOOKUP(F23,$A$6:$C$3205,3,FALSE)
A24: C00019 | B24: R02036 | C24: 1 | D24: exact | F24: C00169 | G24: R02168 | H24: 1 | I24: =VLOOKUP(F24,$A$6:$C$3205,3,FALSE)
A25: C00020 | B25: R01739 | C25: 0.7718 | D25: review | F25: C00171 | G25: R01471 | H25: 1 | I25: =VLOOKUP(F25,$A$6:$C$3205,3,FALSE)
A26: C00021 | B26: R02476 | C26: 1 | D26: exact | F26: C00174 | G26: R01045 | H26: 1 | I26: =VLOOKUP(F26,$A$6:$C$3205,3,FALSE)
A27: C00022 | B27: R00487 | C27: 1 | D27: exact | F27: C00190 | G27: R01903 | H27: 1 | I27: =VLOOKUP(F27,$A$6:$C$3205,3,FALSE)
A28: C00023 | B28: R01823 | C28: 1 | D28: exact | F28: C00192 | G28: R01868 | H28: 1 | I28: =VLOOKUP(F28,$A$6:$C$3205,3,FALSE)
... A305: C00300 | B305: R02870 | C305: 1 | D305: exact | F305: C03177 | G305: R00007 | H305: 1 | I305: =VLOOKUP(F305,$A$6:$C$3205,3,FALSE)
A306: C00301 | B306: R01894 | C306: 0.7718 | D306: review
A307: C00302 | B307: R02400 | C307: 0.6541 | D307: no match
A308: C00303 | B308: R00726 | C308: 0.6541 | D308: no match
A309: C00304 | B309: R00152 | C309: 1 | D309: exact
A310: C00305 | B310: R02105 | C310: 0.7718 | D310: review
A311: C00306 | B311: R01953 | C311: 0.7942 | D311: review
A312: C00307 | B312: R02188 | C312: 1 | D312: exact
A313: C00308 | B313: R00577 | C313: 1 | D313: exact
A314: C00309 | B314: R02629 | C314: 0.6541 | D314: no match
A315: C00310 | B315: R01469 | C315: 1 | D315: exact
A316: C00311 | B316: R00689 | C316: 0.7718 | D316: review
A317: C00312 | B317: R00787 | C317: 1 | D317: exact
...

Sheet S2 Four lists
A1: Sprint 2 · follow one import through both administrations: four questions, four lists
A2: A trader goes on the list of the first question it fails: 1 not known to tax, 2 not filing, 3 import not in its books, 4 sells below what it imports, else consistent for now. I01 is worked in grey. Your class comes from S1 Match, column S. You compute from the two blocks on the right: the lines that bear VAT (rows copied from the Declarations sheet) and the VAT returns (rows copied from the VAT returns sheet); first the steps above them (0, 6 and 7).
A3: Your choice: 4B_lab.xlsx (sheet Lists) already has every number. The checks assume the classes at the dial; if your group linked a review-band pair, its row will differ, and that is your call.
A5: Step | B5: What to do | H5: Your answer | I5: Check | J5: Hint 1 · the tool (the full formula is on the Hints sheet) | X5: Step | Y5: What to do (the columns the extract does not carry: before step 1) | AD5: Your answer | AE5: Check | AG5: Hint 1 (the full formula is on the Hints sheet)
A6: 1 | B6: Columns H and I: imports and import VAT paid over the last twelve months (month 25 on, Parameters), adding up the lines of the lines block on the right (columns X to AE) under the tax number used to clear; with no number, under the importer's own code. They read the month of each line (step 6). Then: the imports of the 25, added up. | H6: =SUM(H17:H41) | I6: =IF(H6="","",IF(ISNUMBER(H6),IF(ABS(H6-_check!$B$18)<=1,"✓ matches","✗ not yet: see the hint"),"✗ not yet: see the hint")) | J6: SUMIFS on the lines block: the value column, by tax number and from the first month of the last twelve; IF the number is blank, by importer code. | X6: 0 | Y6: Step 0, for confident groups: rebuild the lines block from the extract (the line above it says how) and compare the row count. How many lines does the block hold? | AD6: =COUNTA(X17:X12336) | AE6: =IF(AD6="","",IF(ISNUMBER(AD6),IF(ABS(AD6-_check!$B$165)<=0.5,"✓ matches","✗ not yet: see the hint"),"✗ not yet: see the hint")) | AG6: On the extract, filter Declarations on the regime, the date lodged and the tax numbers. Here, COUNTA counts the filled cells of the block's line column.
A7: 2 | B7: Columns J to M: on the tax side (column G), from the returns block on the right (columns AG to AM; they read the period number, step 7): the returns filed of the last six, the import VAT deducted and the sales over twelve months, and booked = deducted ÷ paid. Then: how many of the 25 filed all six of their last six returns? | H7: =COUNTIF(J17:J41,6) | I7: =IF(H7="","",IF(ISNUMBER(H7),IF(ABS(H7-_check!$B$19)<=0.5,"✓ matches","✗ not yet: see the hint"),"✗ not yet: see the hint")) | J7: COUNTIFS on the returns block: the tax number, filed = 1, period number ≥ 19. SUMIFS for the amounts, period number ≥ 13. | X7: 6 | Y7: In the lines block, column AE: the month (1 to 36) of each line, from the date lodged: October 2023 is month 1 (Parameters). T103629's lines are worked; copy down to the last row. How many lines were lodged in month 36? | AD7: =COUNTIF(AE17:AE12336,36) | AE7: =IF(AD7="","",IF(ISNUMBER(AD7),IF(ABS(AD7-_check!$B$166)<=0.5,"✓ matches","✗ not yet: see the hint"),"✗ not yet: see the hint")) | AG7: The date is text (year-month-day): LEFT takes the year, MID the calendar month. Then COUNTIF.
A8: 3 | B8: Columns N and O: sales ÷ imports, and the sector's usual (Sectors sheet). Column P: the first question failed (1 to 5). Column Q: the VAT at stake. Then: how many importers fail question 2 (not filing)? | H8: =COUNTIF(P17:P41,2) | I8: =IF(H8="","",IF(ISNUMBER(H8),IF(ABS(H8-_check!$B$20)<=0.5,"✓ matches","✗ not yet: see the hint"),"✗ not yet: see the hint")) | J8: IF inside IF, in the order of the four questions. VAT at stake, 10%: lists 1-2, VAT × imports × (usual − 1); lists 3-4, VAT × (imports × usual − sales); never below 0. | X8: 7 | Y8: In the returns block, column AM: the period number (1 to 24) of each return, from the period: 2024-10 is period 1 (Parameters). T103629's returns are worked; copy down. How many returns fall in the last twelve periods (period number 13 or more)? | AD8: =COUNTIF(AM17:AM616,">="&Parameters!$B$12) | AE8: =IF(AD8="","",IF(ISNUMBER(AD8),IF(ABS(AD8-_check!$B$167)<=0.5,"✓ matches","✗ not yet: see the hint"),"✗ not yet: see the hint")) | AG8: The period is text (year-month): LEFT and MID again. COUNTIF with ">="& the first period number of the last twelve (Parameters).
A9: 4 | B9: Column R: list 4 ranked by VAT at stake. Column S: the list, cut at the capacity. Then: the VAT at stake within capacity (lists 1 to 3, and list 4 up to the capacity). | H9: =SUMIF(P17:P41,"<=3",Q17:Q41)+SUMIFS(Q17:Q41,P17:P41,4,R17:R41,"<="&Parameters!$B$17) | I9: =IF(H9="","",IF(ISNUMBER(H9),IF(ABS(H9-_check!$B$21)<=1000,"✓ matches","✗ not yet: see the hint"),"✗ not yet: see the hint")) | J9: COUNTIFS counts the list-4 importers with more at stake. The summary table below adds up by list.
A10: 5 | B10: Columns T and U: the lead and the action for each list. Lock list, reason, lead and VAT at stake for the 25 on the site. | J10: List 1: tax, registration letter. List 2: tax, stop-filer letter. List 3: joint, ask for the books. List 4: tax with the customs data, desk audit, largest first.
X14: The lines block (row 17 on): rows copied from the Declarations sheet, as recorded: the lines that bear VAT (home use or release from a warehouse) lodged in months 25 to 36 under the 20 tax numbers of column C, and the lines with no number of the five importers that have none; T103629's first (48 lines, the worked number), then by tax number: 12,320 rows. Column AE is yours (step 6).
AG15: The returns block (row 17 on): rows copied from the VAT returns sheet, as recorded: the 600 returns of the 25 tax numbers the 25 importers can link to (column C, and the register's candidates of S1 Match column G), T103629's first. Column AM is yours (step 7).
A16: ref | B16: importer code | C16: tax number on the declaration | D16: importer (customs) | E16: sector | F16: your class (S1 Match) | G16: tax number on the tax side | H16: imports, 12 months (LCU) | I16: import VAT paid, 12 months (LCU) | J16: returns filed of the last 6 | K16: import VAT deducted, 12 months (LCU) | L16: booked (deducted ÷ paid) | M16: sales, 12 months (LCU) | N16: sales ÷ imports | O16: sector usual | P16: first question failed (1-5) | Q16: VAT at stake (LCU) | R16: rank on list 4 | S16: list | T16: check | U16: lead | V16: action | X16: line | Y16: date lodged | Z16: regime | AA16: importer | AB16: tax number as declared | AC16: customs value (LCU) | AD16: import VAT (LCU) | AE16: month (1-36) · you | AG16: tax number | AH16: period | AI16: filed (1 = yes) | AJ16: sales (LCU) | AK16: purchases (LCU) | AL16: import VAT deducted (LCU) | AM16: period number (1-24) · you
A17: I01 | B17: IMP00519 | C17: T103629 | D17: Ocean Electronics Co., Ltd | E17: Fuel and chemicals | F17: =IF('S1 Match'!S16="","",'S1 Match'!S16) | G17: =IF('S1 Match'!R16="","",'S1 Match'!R16) | H17: =IF(C17="",SUMIFS($AC$17:$AC$12336,$AA$17:$AA$12336,B17,$AE$17:$AE$12336,">="&Parameters!$B$13),SUMIFS($AC$17:$AC$12336,$AB$17:$AB$12336,C17,$AE$17:$AE$12336,">="&Parameters!$B$13)) | I17: =IF(C17="",SUMIFS($AD$17:$AD$12336,$AA$17:$AA$12336,B17,$AE$17:$AE$12336,">="&Parameters!$B$13),SUMIFS($AD$17:$AD$12336,$AB$17:$AB$12336,C17,$AE$17:$AE$12336,">="&Parameters!$B$13)) | J17: =IF(G17="","",COUNTIFS($AG$17:$AG$616,G17,$AI$17:$AI$616,1,$AM$17:$AM$616,">="&Parameters!$B$11)) | K17: =IF(G17="","",SUMIFS($AL$17:$AL$616,$AG$17:$AG$616,G17,$AM$17:$AM$616,">="&Parameters!$B$12)) | L17: =IF(OR(G17="",N(I17)=0),"",K17/I17) | M17: =IF(G17="","",SUMIFS($AJ$17:$AJ$616,$AG$17:$AG$616,G17,$AM$17:$AM$616,">="&Parameters!$B$12)) | N17: =IF(OR(M17="",N(H17)=0),"",M17/H17) | O17: =IFERROR(VLOOKUP(E17,Sectors!$A$5:$B$17,2,FALSE),"") | P17: =IF(G17="",1,IF(J17<Parameters!$B$14,2,IF(L17<Parameters!$B$15,3,IF(N17<Parameters!$B$16,4,5)))) | Q17: =IF(P17<=2,MAX(0,Parameters!$B$10*H17*(O17-1)),IF(P17<=4,MAX(0,Parameters!$B$10*(H17*O17-M17)),0)) | R17: =IF(COUNT($Q$17:$Q$41)<25,"",IF(P17=4,COUNTIFS($P$17:$P$41,4,$Q$17:$Q$41,">"&Q17)+1,"")) | S17: =IF(P17=4,IF(R17="","4 desk audit, ranked by VAT at stake",IF(R17<=Parameters!$B$17,"4 desk audit, ranked by VAT at stake","4b below imports, beyond capacity")),CHOOSE(P17,"1 not known to tax","2 not filing","3 import not booked","","5 consistent for now")) | T17: =IF(OR(H17="",S17="",F17=""),"",IFERROR(IF(AND(ABS(H17-_check!$B$22)<=1,J17=_check!$B$23,ABS(N17-_check!$B$24)<=0.0006),"✓","✗"),"✗")) | X17: L0167865 | Y17: 2025-10-07 | Z17: home_use | AA17: IMP00519 | AB17: T103629 | AC17: 2591057.5 | AD17: 272061.04 | AE17: =(LEFT(Y17,4)-Parameters!$B$23)*12+MID(Y17,6,2)-Parameters!$B$24+1 | AG17: T103629 | AH17: 2024-10 | AI17: 1 | AJ17: 135204943 | AK17: 141092703 | AL17: 13054509 | AM17: =(LEFT(AH17,4)-Parameters!$B$21)*12+MID(AH17,6,2)-Parameters!$B$22+1
A18: I02 | B18: IMP00753 | C18: T105264 | D18: Phoenix Glow Limited | E18: Textiles and apparel | F18: =IF('S1 Match'!S17="","",'S1 Match'!S17) | G18: =IF('S1 Match'!R17="","",'S1 Match'!R17) | H18: =IF(C18="",SUMIFS($AC$17:$AC$12336,$AA$17:$AA$12336,B18,$AE$17:$AE$12336,">="&Parameters!$B$13),SUMIFS($AC$17:$AC$12336,$AB$17:$AB$12336,C18,$AE$17:$AE$12336,">="&Parameters!$B$13)) | I18: =IF(C18="",SUMIFS($AD$17:$AD$12336,$AA$17:$AA$12336,B18,$AE$17:$AE$12336,">="&Parameters!$B$13),SUMIFS($AD$17:$AD$12336,$AB$17:$AB$12336,C18,$AE$17:$AE$12336,">="&Parameters!$B$13)) | J18: =IF(G18="","",COUNTIFS($AG$17:$AG$616,G18,$AI$17:$AI$616,1,$AM$17:$AM$616,">="&Parameters!$B$11)) | K18: =IF(G18="","",SUMIFS($AL$17:$AL$616,$AG$17:$AG$616,G18,$AM$17:$AM$616,">="&Parameters!$B$12)) | L18: =IF(OR(G18="",N(I18)=0),"",K18/I18) | M18: =IF(G18="","",SUMIFS($AJ$17:$AJ$616,$AG$17:$AG$616,G18,$AM$17:$AM$616,">="&Parameters!$B$12)) | N18: =IF(OR(M18="",N(H18)=0),"",M18/H18) | O18: =IFERROR(VLOOKUP(E18,Sectors!$A$5:$B$17,2,FALSE),"") | P18: =IF(G18="",1,IF(J18<Parameters!$B$14,2,IF(L18<Parameters!$B$15,3,IF(N18<Parameters!$B$16,4,5)))) | Q18: =IF(P18<=2,MAX(0,Parameters!$B$10*H18*(O18-1)),IF(P18<=4,MAX(0,Parameters!$B$10*(H18*O18-M18)),0)) | R18: =IF(P18=4,COUNTIFS($P$17:$P$41,4,$Q$17:$Q$41,">"&Q18)+1,"") | S18: =IF(P18=4,IF(R18<=Parameters!$B$17,"4 desk audit, ranked by VAT at stake","4b below imports, beyond capacity"),CHOOSE(P18,"1 not known to tax","2 not filing","3 import not booked","","5 consistent for now")) | T18: =IF(OR(H18="",S18="",F18=""),"",IFERROR(IF(AND(ABS(H18-_check!$B$25)<=1,J18=_check!$B$26,ABS(N18-_check!$B$27)<=0.0006),"✓","✗"),"✗")) | X18: L0169800 | Y18: 2025-10-16 | Z18: home_use | AA18: IMP00519 | AB18: T103629 | AC18: 18915339 | AD18: 1891533.9 | AE18: =(LEFT(Y18,4)-Parameters!$B$23)*12+MID(Y18,6,2)-Parameters!$B$24+1 | AG18: T103629 | AH18: 2024-11 | AI18: 1 | AJ18: 139784358 | AK18: 145871538 | AL18: 13303999 | AM18: =(LEFT(AH18,4)-Parameters!$B$21)*12+MID(AH18,6,2)-Parameters!$B$22+1
A19: I03 | B19: IMP00892 | C19: T106240 | D19: Delta Fruits Holdings Ltd | E19: General trading | F19: =IF('S1 Match'!S18="","",'S1 Match'!S18) | G19: =IF('S1 Match'!R18="","",'S1 Match'!R18) | H19: =IF(C19="",SUMIFS($AC$17:$AC$12336,$AA$17:$AA$12336,B19,$AE$17:$AE$12336,">="&Parameters!$B$13),SUMIFS($AC$17:$AC$12336,$AB$17:$AB$12336,C19,$AE$17:$AE$12336,">="&Parameters!$B$13)) | I19: =IF(C19="",SUMIFS($AD$17:$AD$12336,$AA$17:$AA$12336,B19,$AE$17:$AE$12336,">="&Parameters!$B$13),SUMIFS($AD$17:$AD$12336,$AB$17:$AB$12336,C19,$AE$17:$AE$12336,">="&Parameters!$B$13)) | J19: =IF(G19="","",COUNTIFS($AG$17:$AG$616,G19,$AI$17:$AI$616,1,$AM$17:$AM$616,">="&Parameters!$B$11)) | K19: =IF(G19="","",SUMIFS($AL$17:$AL$616,$AG$17:$AG$616,G19,$AM$17:$AM$616,">="&Parameters!$B$12)) | L19: =IF(OR(G19="",N(I19)=0),"",K19/I19) | M19: =IF(G19="","",SUMIFS($AJ$17:$AJ$616,$AG$17:$AG$616,G19,$AM$17:$AM$616,">="&Parameters!$B$12)) | N19: =IF(OR(M19="",N(H19)=0),"",M19/H19) | O19: =IFERROR(VLOOKUP(E19,Sectors!$A$5:$B$17,2,FALSE),"") | P19: =IF(G19="",1,IF(J19<Parameters!$B$14,2,IF(L19<Parameters!$B$15,3,IF(N19<Parameters!$B$16,4,5)))) | Q19: =IF(P19<=2,MAX(0,Parameters!$B$10*H19*(O19-1)),IF(P19<=4,MAX(0,Parameters!$B$10*(H19*O19-M19)),0)) | R19: =IF(P19=4,COUNTIFS($P$17:$P$41,4,$Q$17:$Q$41,">"&Q19)+1,"") | S19: =IF(P19=4,IF(R19<=Parameters!$B$17,"4 desk audit, ranked by VAT at stake","4b below imports, beyond capacity"),CHOOSE(P19,"1 not known to tax","2 not filing","3 import not booked","","5 consistent for now")) | T19: =IF(OR(H19="",S19="",F19=""),"",IFERROR(IF(AND(ABS(H19-_check!$B$28)<=1,J19=_check!$B$29,ABS(N19-_check!$B$30)<=0.0006),"✓","✗"),"✗")) | X19: L0170266 | Y19: 2025-10-18 | Z19: home_use | AA19: IMP00519 | AB19: T103629 | AC19: 11895689 | AD19: 1368004.3 | AE19: =(LEFT(Y19,4)-Parameters!$B$23)*12+MID(Y19,6,2)-Parameters!$B$24+1 | AG19: T103629 | AH19: 2024-12 | AI19: 1 | AJ19: 189409600 | AK19: 197657807 | AL19: 17993668 | AM19: =(LEFT(AH19,4)-Parameters!$B$21)*12+MID(AH19,6,2)-Parameters!$B$22+1
A20: I04 | B20: IMP00340 | C20: T102376 | D20: Great Vellmoor Steel Enterprises | E20: Fuel and chemicals | F20: =IF('S1 Match'!S19="","",'S1 Match'!S19) | G20: =IF('S1 Match'!R19="","",'S1 Match'!R19) | H20: =IF(C20="",SUMIFS($AC$17:$AC$12336,$AA$17:$AA$12336,B20,$AE$17:$AE$12336,">="&Parameters!$B$13),SUMIFS($AC$17:$AC$12336,$AB$17:$AB$12336,C20,$AE$17:$AE$12336,">="&Parameters!$B$13)) | I20: =IF(C20="",SUMIFS($AD$17:$AD$12336,$AA$17:$AA$12336,B20,$AE$17:$AE$12336,">="&Parameters!$B$13),SUMIFS($AD$17:$AD$12336,$AB$17:$AB$12336,C20,$AE$17:$AE$12336,">="&Parameters!$B$13)) | J20: =IF(G20="","",COUNTIFS($AG$17:$AG$616,G20,$AI$17:$AI$616,1,$AM$17:$AM$616,">="&Parameters!$B$11)) | K20: =IF(G20="","",SUMIFS($AL$17:$AL$616,$AG$17:$AG$616,G20,$AM$17:$AM$616,">="&Parameters!$B$12)) | L20: =IF(OR(G20="",N(I20)=0),"",K20/I20) | M20: =IF(G20="","",SUMIFS($AJ$17:$AJ$616,$AG$17:$AG$616,G20,$AM$17:$AM$616,">="&Parameters!$B$12)) | N20: =IF(OR(M20="",N(H20)=0),"",M20/H20) | O20: =IFERROR(VLOOKUP(E20,Sectors!$A$5:$B$17,2,FALSE),"") | P20: =IF(G20="",1,IF(J20<Parameters!$B$14,2,IF(L20<Parameters!$B$15,3,IF(N20<Parameters!$B$16,4,5)))) | Q20: =IF(P20<=2,MAX(0,Parameters!$B$10*H20*(O20-1)),IF(P20<=4,MAX(0,Parameters!$B$10*(H20*O20-M20)),0)) | R20: =IF(P20=4,COUNTIFS($P$17:$P$41,4,$Q$17:$Q$41,">"&Q20)+1,"") | S20: =IF(P20=4,IF(R20<=Parameters!$B$17,"4 desk audit, ranked by VAT at stake","4b below imports, beyond capacity"),CHOOSE(P20,"1 not known to tax","2 not filing","3 import not booked","","5 consistent for now")) | T20: =IF(OR(H20="",S20="",F20=""),"",IFERROR(IF(AND(ABS(H20-_check!$B$31)<=1,J20=_check!$B$32,ABS(N20-_check!$B$33)<=0.0006),"✓","✗"),"✗")) | X20: L0172414 | Y20: 2025-10-28 | Z20: home_use | AA20: IMP00519 | AB20: T103629 | AC20: 7420869 | AD20: 779191.24 | AE20: =(LEFT(Y20,4)-Parameters!$B$23)*12+MID(Y20,6,2)-Parameters!$B$24+1 | AG20: T103629 | AH20: 2025-01 | AI20: 1 | AJ20: 53949516 | AK20: 56298852 | AL20: 5207983 | AM20: =(LEFT(AH20,4)-Parameters!$B$21)*12+MID(AH20,6,2)-Parameters!$B$22+1
A21: I05 | B21: IMP00999 | C21: T106987 | D21: Carrick Electronics Group Ltd | E21: Electronics | F21: =IF('S1 Match'!S20="","",'S1 Match'!S20) | G21: =IF('S1 Match'!R20="","",'S1 Match'!R20) | H21: =IF(C21="",SUMIFS($AC$17:$AC$12336,$AA$17:$AA$12336,B21,$AE$17:$AE$12336,">="&Parameters!$B$13),SUMIFS($AC$17:$AC$12336,$AB$17:$AB$12336,C21,$AE$17:$AE$12336,">="&Parameters!$B$13)) | I21: =IF(C21="",SUMIFS($AD$17:$AD$12336,$AA$17:$AA$12336,B21,$AE$17:$AE$12336,">="&Parameters!$B$13),SUMIFS($AD$17:$AD$12336,$AB$17:$AB$12336,C21,$AE$17:$AE$12336,">="&Parameters!$B$13)) | J21: =IF(G21="","",COUNTIFS($AG$17:$AG$616,G21,$AI$17:$AI$616,1,$AM$17:$AM$616,">="&Parameters!$B$11)) | K21: =IF(G21="","",SUMIFS($AL$17:$AL$616,$AG$17:$AG$616,G21,$AM$17:$AM$616,">="&Parameters!$B$12)) | L21: =IF(OR(G21="",N(I21)=0),"",K21/I21) | M21: =IF(G21="","",SUMIFS($AJ$17:$AJ$616,$AG$17:$AG$616,G21,$AM$17:$AM$616,">="&Parameters!$B$12)) | N21: =IF(OR(M21="",N(H21)=0),"",M21/H21) | O21: =IFERROR(VLOOKUP(E21,Sectors!$A$5:$B$17,2,FALSE),"") | P21: =IF(G21="",1,IF(J21<Parameters!$B$14,2,IF(L21<Parameters!$B$15,3,IF(N21<Parameters!$B$16,4,5)))) | Q21: =IF(P21<=2,MAX(0,Parameters!$B$10*H21*(O21-1)),IF(P21<=4,MAX(0,Parameters!$B$10*(H21*O21-M21)),0)) | R21: =IF(P21=4,COUNTIFS($P$17:$P$41,4,$Q$17:$Q$41,">"&Q21)+1,"") | S21: =IF(P21=4,IF(R21<=Parameters!$B$17,"4 desk audit, ranked by VAT at stake","4b below imports, beyond capacity"),CHOOSE(P21,"1 not known to tax","2 not filing","3 import not booked","","5 consistent for now")) | T21: =IF(OR(H21="",S21="",F21=""),"",IFERROR(IF(AND(ABS(H21-_check!$B$34)<=1,J21=_check!$B$35,ABS(N21-_check!$B$36)<=0.0006),"✓","✗"),"✗")) | X21: L0175617 | Y21: 2025-11-14 | Z21: home_use | AA21: IMP00519 | AB21: T103629 | AC21: 2962327.8 | AD21: 311044.42 | AE21: =(LEFT(Y21,4)-Parameters!$B$23)*12+MID(Y21,6,2)-Parameters!$B$24+1 | AG21: T103629 | AH21: 2025-02 | AI21: 1 | AJ21: 162229768 | AK21: 169294377 | AL21: 14947581 | AM21: =(LEFT(AH21,4)-Parameters!$B$21)*12+MID(AH21,6,2)-Parameters!$B$22+1
